Workbook
Name ADRESSA: '契約金振り込み依頼書'!$AO$7:$AP$15
Name ADRESSB: '契約金振り込み依頼書'!$AO$7:$AO$15

Sheet 初期入力
A1: 初期入力欄 | B1: （ピンク色の箇所に記入またはタブで選択お願いします）
A2: 請負契約書入力分
A3: 工事名称 | B3: 大阪市旭区新森 テスト太郎様邸新築工事 | I3: ★マークがついているタブは単独名義の場合、一部削除する操作必要
A4: 客先氏名 | B4: テスト太郎
A5: 客先住所 | B5: 大阪府大阪市中央区本町1-1-1
A6: 客先氏名2 | B6: テスト花子 | D6: 様 | E6: ←連名の場合は2列目に様を入力する
A7: 客先住所2 | B7: 大阪府大阪市中央区本町1-1-1 | I7: ↓下記4列はプルダウンで選択してください。
A8: 重要事項説明者 | B8: 田中 聡 | I8: ←重要事項説明書を依頼する方を選択してください。
A9: 建築士登録番号 | B9: =IFERROR(VLOOKUP(B8, L18:O28, 3, FALSE), "値が見つかりません") -> 一級 | C9: 建築士 | D9: =VLOOKUP(B8, L18:O28, 4, FALSE) -> 大臣 | E9: 登録第 | F9: =VLOOKUP($B$8,$L$18:$M$28,2,0) -> 253424 | G9: ←3つ選択必要 | I9: 田中 聡（一級）建築士【大臣登録】（第253424号） 佐古 祐太（二級）建築士 大阪府知事登録（第58870号)
A10: 建築士の種類 | B10: =IF(B8="田中 聡", "■管理建築士 □所属する建築士", "□管理建築士 ■所属する建築士") -> ■管理建築士 □所属する建築士 | I10: ←田中さんは【管理建築士】、それ以外の方は【所属する建築士】の■になっているタブを選んでください。
A11: 単独or共有 | B11: 共有 | I11: 西野 秀樹（一級）建築士【大臣登録】（第332632号） 箕浦 三四郎（一級）建築士【大臣登録】（第354989号）
A12: 営業担当 | B12: 田畑 美香 | I12: 古久保 知佳子（二級）大阪府知事登録（第56598号) 村上 由貴子（二級）京都府知事登録（第18527号）
A13: 請負契約日 | C13: 2026 | D13: 年 | E13: 1 | F13: 月 | G13: 15 | H13: 日 | I13: ←数字のみ入力必要 | L13: 林 恭生（二級）和歌山県知事（第6667） 北村 晃平（一級）【大臣登録】（第362717号）
A14: 変更契約日 | C14: 2026 | D14: 年 | E14: 3 | F14: 月 | G14: 15 | H14: 日 | L14: 安藤 千智 （二級）建築士 京都府知事登録（第19339号）
A15: 工事場所 | B15: 大阪府大阪市旭区新森1-2-3 | I15: ←【地番記載】謄本通りの書き方にて
A16: 構造 | B16: 木造軸組工法
A17: 建物階数 | B17: 2 | E17: 変更契約→ | F17: 2 | I17: ←階数選択 | L17: 設計担当 | M17: 番号 | N17: 級 | O17: 登録
A18: 棟数 | B18: 1 | F18: 1 | L18: 田中 聡 | M18: 253424 | N18: 一級 | O18: 大臣
A19: 1階床面積 | B19: 49.04 | I19: ←面積表通り記載 | L19: 北村 晃平 | M19: 362717 | N19: 一級 | O19: 大臣
A20: 対象の場合〇入力 | B20: 〇 | F20: 〇 | L20: 林 恭生 | M20: 6667 | N20: 二級 | O20: 和歌山県知事
A21: 2階床面積 | B21: 44.81 | I21: ←面積表通り記載 | L21: 箕浦 三四郎 | M21: 354989 | N21: 一級 | O21: 大臣
A22: 対象の場合〇入力 | B22: 〇 | F22: 〇 | L22: 荘野 善宏 | M22: 10409 | N22: 二級 | O22: 三重県知事
A23: 3階床面積 | B23: 0 | I23: ←面積表通り記載 | L23: 内藤 智之 | M23: 44439 | N23: 二級 | O23: 大阪府知事
A24: 対象の場合〇入力 | L24: 足立 雅哉 | M24: 319770 | N24: 一級 | O24: 大臣
A25: 施工面積 | B25: 28.4 | L25: 若狹 龍成 | M25: 9571 | N25: 二級 | O25: 愛媛県知事
A26: 対象の場合〇入力 | B26: 〇 | F26: 〇 | L26: 髙濱 洋文 | M26: 305600 | N26: 一級 | O26: 大臣
A27: 着手期日 | B27: 46143 | F27: =B27 -> 45861 | I27: ←資金計画書通り記載 | L27: 佐古 祐太 | M27: 58870 | N27: 二級 | O27: 大阪府知事
A28: 完成期日 | B28: 46295 | F28: =B28 -> 46042 | I28: 令和の年数注意 | L28: 古久保 知佳子 | M28: 56598 | N28: 二級 | O28: 大阪府知事
A29: 引渡期日 | B29: 46310 | F29: =B29 -> 46066
A30: 契約日 | B30: 46037 | F30: 45923
A31: 工事価格(税抜き） | B31: 25208700 | I31: ←数字間違い、位間違い注意
A32: 取引に関わる消費税 | B32: =ROUNDDOWN(B31*0.1,0) -> 2520870 | F32: =ROUNDDOWN(F31*0.1,0) -> 0
A33: 合計額(請負代金） | B33: =SUM(B31:D32) -> 27729570 | F33: =SUM(F31:H32) -> 0
A34: 1回金 建築申込時 | B34: 100000 | F34: =B34 -> 100000
A35: お支払い予定日 | B35: 45992 | F35: =IF((初期入力!B35)="","",初期入力!B35) -> 45356 | I35: ←令和の年数注意
A36: 2回金 請負契約時 | B36: 1000000 | F36: =B36 -> 1000000
A37: お支払い予定日 | B37: 46037 | F37: =B37 -> 45376
A38: 3回金 着工時 | B38: 8300000 | F38: =B38 -> 8300000
A39: お支払い予定日 | B39: 46143 | F39: =B39 -> 46233
A40: 4回金 上棟時 | B40: 8300000 | F40: =B40 -> 8300000
...

Sheet ★重要事項説明書・省エネ説明義務化
A1: 重 要 事 項 説 明 書
N2: =初期入力!C13 -> 2025 | P2: 年 | Q2: =初期入力!E13 -> 7 | R2: 月 | S2: =初期入力!G13 -> 25 | T2: 日
A3: =初期入力!B4 -> 0 | F3: 様
A4: =IF(初期入力!B6="","",初期入力!B6) | F4: =初期入力!D6 -> 様 | V4: ←単独の場合削除 A～Ｆを選択してＤｅｌｅｔｅボタンを押してください。
A6: 本重要事項説明は、建築士法第24条の7に基づき、設計受託契約又は工事監理受託契約に先立って、あらかじめ契
A7: 約の内容及びその履行に関する事項を説明するものです。本説明内容は最終的な契約内容とは必ずしも同一になる | V7: ※JIO瑕疵担保保険の重要事項説明のビデオ鑑賞・契約確認シート記名押印も合わせてすること！
A8: とは限りません。
A10: 受託業務名称： | D10: =初期入力!B3 -> 大阪市旭区新森 池田様邸新築工事 | K10: 設計・工事監理業務
A12: 建築士事務所の名称 | G12: ： | H12: 株式会社Gハウス 一級建築士事務所
A13: 建築士事務所の所在地 | G13: ： | H13: 大阪府大阪市旭区新森2-23-12
A14: 開設者氏名 | G14: ： | H14: 株式会社Gハウス 代表取締役 趙 晃啓
A15: (法人の場合は開設者の名称及び代表者氏名)
A18: 1.対象となる建築物の概要
A19: 建設予定地 | E19: ： | F19: =初期入力!B15 -> 大阪府大阪市旭区新森
A20: 主要用途 | E20: ： | F20: 一戸建ての住宅
A21: 工事種別 | E21: ： | F21: 新築
A22: 規模等 | E22: ： | F22: =初期入力!B16 -> 木造軸組工法 | J22: =初期入力!B17 -> 2 | K22: 階建て | M22: =工事請負契約書!F111 -> 100.95 | O22: ㎡
A24: 2.作成する設計図書の種類(設計契約受託の場合)
A25: 案内図、配置図、求積図、平面図、立面図、断面図、その他建築確認申請図書一式
A32: 3.工事と設計図書との照合の方法及び工事監理の実施状況に関する報告の方法
C33: (工事監理契約受託の場合)
A34: ①工事と設計図書との照合の方法：
A35: 施工業者からの施工報告及び現場監督からの現場管理報告により確認します。
A36: 特定工程 | C36: =IF(J22=2,"1回","2回") -> 1回 | D36: 、完了検査 | F36: 1回 | G36: による合計 | I36: =IF(J22=2,"2回","3回") -> 2回 | J36: の現場立会検査。
A37: ②工事監理の実施状況に関する報告の方法：
A38: 特定工程の検査済証、施工資料及び施工写真を提出します。
A39: 完了検査の検査済証、施工資料及び施工写真を提出します。
A42: 4.設計又は工事監理の一部を委託する場合の計画 | W42: 構造設計
A43: ①設計又は工事監理の一部を委託する予定： | J43: ■あり □なし | W43: 株式会社ワークスワン
A44: ②委託する業務の概要及び委託先（ありの場合の計画） | W44: 大阪市西区南堀江1-2-6サムティ南堀江ビル6F
A45: 委託する業務の概要 | G45: ： | H45: 構造設計 | W45: 大賀 信幸
A46: 建築士事務所の名称 | G46: ： | H46: 株式会社ワークスワン
A47: 建築士事務所の名称所在地 | G47: ： | H47: 大阪市西区南堀江1-2-6サムティ南堀江ビル6F | W47: 構造設計
A48: 開設者氏名 | G48: ： | H48: 大賀 信幸 | W48: Taki建築設計
W49: 大阪府泉南市信達大苗代1123-6
A50: 委託する業務の概要 | G50: ： | H50: 該当なし | W50: 瀧本 護
A51: 建築士事務所の名称 | G51: ：
A52: 建築士事務所の所在地 | G52: ：
A53: 開設者氏名 | G53: ：
A56: 5.設計又は工事監理に従事することとなる建築士・建築設備士
...

Sheet 工事請負契約書
B2: NO. | C2: =初期入力!B44 -> 103824
A10: =初期入力!B3 -> 大阪市旭区新森 池田様邸新築工事
A14: 建築工事請負契約書
D53: 株式会社 Gハウス
S56: 20250724 | W56: 制定
D59: 建築工事請負契約書
A63: 注文者： | D63: =初期入力!B4 -> 0 | I63: =IF(初期入力!B6="","",初期入力!B6) | P63: (以下「甲」という)と
A65: 請負者： | D65: 株式会社 Gハウス | P65: (以下「乙」という)とは
D67: =初期入力!B3 -> 大阪市旭区新森 池田様邸新築工事
A69: の施工について、次の各条項・資金計画書・設計図書・その他添付資料に基づき請負契約を締結し、
A70: 契約成立を証するため、本書の電磁的記録を作成し、甲および乙が合意の後電子署名を施し、各自
A71: 電磁的記録を保管する。
A74: なお、この請負契約書に添付の設計図書は、参考図面であり確定図面でないものとします。
A75: この請負契約締結後、甲乙協議の上、確定設計図書を作成するものとします。
K79: =初期入力!C13 -> 2025 | M79: 年 | N79: =初期入力!E13 -> 7 | P79: 月 | Q79: =初期入力!G13 -> 25 | S79: 日
A82: 甲1住所 | D82: =初期入力!B5 -> 0
A84: 甲1氏名 | D84: =初期入力!B4 -> 0 | Q84: 印
A86: 甲2住所 | D86: =IF(初期入力!B7="","",初期入力!B7)
A88: 甲2氏名 | D88: =IF(初期入力!B6="","",初期入力!B6) | Q88: 印
A90: 乙住所 | D90: 大阪府大阪市旭区新森2-23-12
A92: 乙氏名 | D92: 株式会社 Gハウス | J92: 代表取締役 趙晃啓 | Q92: 印
A96: 工事名称 | D96: =初期入力!B3 -> 大阪市旭区新森 池田様邸新築工事 | K96: 新・増・改 | P96: 建物所有形態
K97: 築工事 | P97: =初期入力!B11 -> 共有
A98: 工事場所 | D98: =初期入力!B15 -> 大阪府大阪市旭区新森
A100: 構 造 | D100: =初期入力!B16 -> 木造軸組工法 | J100: =初期入力!B17 -> 2 | M100: 階建 | P100: =初期入力!B18 -> 1 | T100: 棟
A103: =初期入力!B20 -> 〇 | B103: 1階床面積 | E103: ㎡ | F103: =初期入力!B19 -> 49.04 | I103: 工 期 | K103: 官庁許可日から 60日 以内に着工予定
I104: 着手期日 | K104: =初期入力!B27 -> 45861
A105: =IF(初期入力!B22="","",初期入力!B22) -> 〇 | B105: 2階床面積 | E105: ㎡ | F105: =初期入力!B21 -> 44.81 | K105: 着手の日から 180日 以内に完成予定
I106: 完成期日 | K106: =初期入力!B28 -> 46042
A107: =IF(初期入力!B24="","",初期入力!B24) | B107: 3階床面積 | E107: ㎡ | F107: =初期入力!B23 -> 0 | K107: 完成の日から 60日 以内に引渡予定
I108: 引渡期日 | K108: =初期入力!B29 -> 46066
A109: =IF(初期入力!B26="","",初期入力!B26) -> 〇 | B109: 施工面積 | E109: ㎡ | F109: =初期入力!B25 -> 7.1
B111: 工事面積 合計 | E111: ㎡ | F111: =F103+F105+F109+F107 -> 100.95
A114: 工事価格(消費税額を除く) | H114: 金 | I114: =初期入力!B31 -> 25208700 | L114: 円也
A115: 取引に係る消費税額 | H115: 金 | I115: =初期入力!B32 -> 2520870 | L115: 円也
A116: 合計額(請負代金) | H116: 金 | I116: =初期入力!B33 -> 27729570 | L116: 円也
A118: 回 次 | D118: お支払時期 | G118: お支払金額 | M118: お支払予定日
A119: 合計額の支払方法 | B119: 1回金 | D119: 建築申込時 | H119: 金 | I119: =初期入力!B34 -> 100000 | L119: 円也 | M119: =IF((初期入力!B35)="","",初期入力!B35) -> 45356
B120: 2回金 | D120: 請負契約時 | H120: 金 | I120: =初期入力!B36 -> 1000000 | L120: 円也 | M120: =初期入力!B37 -> 45376
B121: 3回金 | D121: 着工時 | H121: 金 | I121: =初期入力!B38 -> 8300000 | L121: 円也 | M121: =初期入力!B39 -> 46233
...

Sheet 追加変更請負契約書 
B2: NO. | C2: =初期入力!B44 -> 103824
A10: =初期入力!B3 -> 大阪市旭区新森 池田様邸新築工事
A14: 建築工事追加変更請負契約書
C52: 株式会社 Gハウス
P55: 20250616 | T55: 制定
D58: 建築工事追加変更請負契約書
A62: 注文者： | D62: =初期入力!B4 -> 0 | H62: =IF(初期入力!B6="","",初期入力!B6) | R62: (以下「甲」という)と
A64: 請負者： | D64: 株式会社 Gハウス | R64: (以下「乙」という)とは
D66: =初期入力!B3 -> 大阪市旭区新森 池田様邸新築工事
A68: の施工について、次の各条項･資金計画書･設計図書･その他添付資料に基づき追加変更請負契約
A69: を締結し、契約成立を証するため、本書の電磁的記録を作成し、甲および乙が合意の後電子署名を施し、
A70: 各自電磁的記録を保管する。
J75: =初期入力!C14 -> 2026 | L75: 年 | M75: =初期入力!E14 -> 12 | O75: 月 | P75: =初期入力!G14 -> 25 | R75: 日
A78: 甲１住所 | D78: =初期入力!B5 -> 0
A80: 甲１氏名 | D80: =初期入力!B4 -> 0 | Q80: 印
A82: 甲２住所 | D82: =IF(初期入力!B7="","",初期入力!B7)
A84: 甲２氏名 | D84: =IF(初期入力!B6="","",初期入力!B6) | Q84: 印
A86: 乙住所 | D86: 大阪府大阪市旭区新森2-23-12
A88: 乙氏名 | D88: 株式会社 Gハウス | I88: 代表取締役 趙晃啓 | Q88: 印
A92: 工事名称 | D92: =初期入力!B3 -> 大阪市旭区新森 池田様邸新築工事 | K92: 新 増 改 | N92: 建物所有形態
K93: 築工事 | N93: =初期入力!B11 -> 共有
A94: 工事場所 | D94: =初期入力!B15 -> 大阪府大阪市旭区新森
A96: 構 造 | D96: =初期入力!B16 -> 木造軸組工法 | J96: =初期入力!B17 -> 2 | M96: 階建 | N96: =初期入力!B18 -> 1 | T96: 棟
A99: =初期入力!B20 -> 〇 | B99: 1階床面積 | E99: ㎡ | F99: =初期入力!F19 -> 0 | I99: 工 期 | L99: 官庁許可日から 60日 以内に着工予定
I100: 着手期日 | L100: =初期入力!F27 -> 45861
A101: =IF(初期入力!B22="","",初期入力!B22) -> 〇 | B101: 2階床面積 | E101: ㎡ | F101: =初期入力!F21 -> 0 | L101: 着手の日から 180日 以内に完成予定
I102: 完成期日 | L102: =初期入力!F28 -> 46042
A103: =IF(初期入力!B24="","",初期入力!B24) | B103: 3階床面積 | E103: ㎡ | F103: =初期入力!F23 -> 0 | L103: 完成の日から 60日 以内に引渡予定
I104: 引渡期日 | L104: =初期入力!F27 -> 45861
A105: =IF(初期入力!B26="","",初期入力!B26) -> 〇 | B105: 施工面積 | E105: ㎡ | F105: =初期入力!F25 -> 0
B107: 工事面積 合計 | E107: ㎡ | F107: =F99+F101+F103+F105 -> 0
A110: 工事価格(消費税額を除く) | H110: 金 | I110: =初期入力!F31 -> 0 | M110: 円也
A111: 取引に係る消費税額 | H111: 金 | I111: =初期入力!F32 -> 0 | M111: 円也
A112: 合計額(請負代金) | H112: 金 | I112: =初期入力!F33 -> 0 | M112: 円也
A114: 回 次 | D114: お支払時期 | G114: お支払金額 | N114: お支払予定日
A115: 合計額の支払方法 | B115: 1回金 | D115: 建築申込時 | H115: 金 | I115: =初期入力!F34 -> 100000 | M115: 円也 | N115: =IF(初期入力!F35="","",初期入力!F35) -> 45356
B116: 2回金 | D116: 請負契約時 | H116: 金 | I116: =初期入力!F36 -> 1000000 | M116: 円也 | N116: =初期入力!F37 -> 45376
B117: 3回金 | D117: 着工時 | H117: 金 | I117: =初期入力!F38 -> 8300000 | M117: 円也 | N117: =初期入力!F39 -> 46233
B118: 4回金 | D118: 上棟時 | H118: 金 | I118: =初期入力!F40 -> 8300000 | M118: 円也 | N118: =初期入力!F41 -> 46273
B119: 5回金 | D119: 引渡時 | H119: 金 | I119: =初期入力!F42 -> -17700000 | M119: 円也 | N119: =初期入力!F43 -> 46066
...

Sheet 変更合意書
B1: 工事請負契約に関する一部変更合意書
P3: NO. | Q3: =初期入力!B44 -> 103824
A4: 下記契約当事者の発注者・受注者間において締結した | F4: =初期入力!C13 -> 2025 | G4: 年 | H4: =初期入力!E13 -> 7 | I4: 月 | J4: =初期入力!G13 -> 25 | K4: 日 | L4: 付 | M4: =初期入力!B3 -> 大阪市旭区新森 池田様邸新築工事
A5: 請負契約書(以下｢原契約書｣という)に関する契約事項の一部について下記の通り変更する事に合意する。
A6: 尚、本合意書に定める事項以外については、原契約書の定めを適用するものとする。
A7: この契約の証として、本書の電磁的記録を作成し、甲および乙が合意の後電子署名を施し、
A8: 各自電磁的記録を保管する。
E9: 記
A10: 項目 | C10: 変更前の契約事項 | H10: 変更後の合意事項
A11: 1 工事内容 | C11: 原契約書添付の設計図、見積書の通り | H11: 本合意書添付の設計図、見積書の通り
A12: 2 工事名称 | C12: 注文者(甲) | H12: 注文者(甲)
C13: 住所 | D13: =初期入力!B5 -> 0 | H13: 住所
C14: 氏名 | D14: =初期入力!B4 -> 0 | H14: 氏名
A15: 但し、寄託した契約証拠金等の付随的な契約上の地位はそのまま、変更後の原契約に包括承継される。 | C15: 住所 | D15: =IF(初期入力!B7="","",初期入力!B7) | H15: 住所
C16: 氏名 | D16: =IF(初期入力!B6="","",初期入力!B6) | H16: 氏名
A17: 3 工事場所
A18: 4 工事面積 | C18: ㎡ | K18: ㎡
A19: 5 工期 | C19: 着工 | D19: 年 月 日 | H19: 着工 | M19: 年 月 日
C20: 引渡 | D20: 年 月 日 | H20: 引渡 | M20: 年 月 日
A21: 6 請負代金 | C21: 原契約書記載の通り | H21: (増･減額) | Q21: 円
C22: 請負代金 | H22: 請負代金
C23: (消費税込) | G23: 円 | H23: (消費税込) | Q23: 円
A24: 7 請負代金の 支払い条件 | E24: 金額 | L24: 金額
C25: 建築申込金 | G25: 円 | H25: 建築申込金 | Q25: 円
C26: 契約金 | G26: 円 | H26: 契約金 | Q26: 円
A27: 変更部分のみ記載 | C27: 着工金 | G27: 円 | H27: 着工金 | Q27: 円
C28: 上棟金 | G28: 円 | H28: 上棟金 | Q28: 円
C29: 最終金 | G29: 円 | H29: 最終金 | Q29: 円
A30: 8 その他
A33: 年 月 日
C34: 住所 | E34: =初期入力!B5 -> 0
C35: 注文者(甲) | E35: =初期入力!B4 -> 0 | P35: 印
C37: 住所 | E37: =初期入力!B7 -> 0
C38: 注文者(甲) | E38: =初期入力!B6 -> 0 | P38: 印
C40: 住所 | E40: 大阪府大阪市旭区新森2-23-12
E41: 株式会社Gハウス
C42: 請負者(乙) | E42: 代表取締役 趙 晃啓 | P42: 印

Sheet HOURS以外制約事項
D1: LIFE+ | E1: の仕様 制約事項一覧 | I1: ←商品名タブにて選択必要
C2: 項目 | D2: 標準内容 | F2: 備考
A3: □ | B3: 1 | C3: 間取り | D3: =IF($D$1="LACIE",VLOOKUP(C3,作業用タブ1!$D$2:$F$27,2,FALSE),IF($D$1="LIFE+",VLOOKUP(C3,作業用タブ1!$D$33:$F$58,2,FALSE),IF($D$1="LIFE",VLOOKUP(C3,作業用タブ1!$D$64:$F$89,2,FALSE),IF($D$1="BASE",VLOOKUP(C3,作業用タブ1!$D$95:$F$120,2,FALSE),IF($D$1="LIFE+（キャンペーン）",VLOOKUP(C3,作業用タブ1!$D$126:$F$151,2,FALSE),IF($D$1="LIFE（キャンペーン）",VLOOKUP(C3,作業用タブ1!$D$157:$F$182,2,FALSE),IF($D$1="LIFE+（キャンペーン）",VLOOKUP(C3,作業用タブ1!$D$126:$F$151,2,FALSE),IF($D$1="LIFE（キャンペーン）",VLOOKUP(C3,作業用タブ1!$D$157:$F$182,2,FALSE))))))))) -> 完全自由設計 ※4マス×910mm間隔に柱または壁の設置が必要です。 | F3: =IF($D$1="LACIE",VLOOKUP(C3,作業用タブ1!$D$2:$F$27,3,FALSE),IF($D$1="LIFE+",VLOOKUP(C3,作業用タブ1!$D$33:$F$58,3,FALSE),IF($D$1="LIFE",VLOOKUP(C3,作業用タブ1!$D$64:$F$89,3,FALSE),IF($D$1="BASE",VLOOKUP(C3,作業用タブ1!$D$95:$F$120,3,FALSE),IF($D$1="LIFE+（キャンペーン）",VLOOKUP(C3,作業用タブ1!$D$126:$F$151,3,FALSE),IF($D$1="LIFE（キャンペーン）",VLOOKUP(C3,作業用タブ1!$D$157:$F$182,3,FALSE))))))) -> 申請業務に進んでいくため、基本設計確定後の変更は出来ません。
A4: □ | B4: 2 | C4: 坪単価 | D4: =IF($D$1="LACIE",VLOOKUP(C4,作業用タブ1!$D$2:$F$27,2,FALSE),IF($D$1="LIFE+",VLOOKUP(C4,作業用タブ1!$D$33:$F$58,2,FALSE),IF($D$1="LIFE",VLOOKUP(C4,作業用タブ1!$D$64:$F$89,2,FALSE),IF($D$1="BASE",VLOOKUP(C4,作業用タブ1!$D$95:$F$120,2,FALSE),IF($D$1="LIFE+（キャンペーン）",VLOOKUP(C4,作業用タブ1!$D$126:$F$151,2,FALSE),IF($D$1="LIFE（キャンペーン）",VLOOKUP(C4,作業用タブ1!$D$157:$F$182,2,FALSE))))))) -> 本体工事価格は 63万円(税別) 30坪未満の場合割増計算となり、1坪下がる度に15,000円×坪数＝追加費用が発生します。 3階建ての場合は坪単価＋40,000円UP 下屋の場合は下屋部分㎡×30,000円UP | F4: =IF($D$1="LACIE",VLOOKUP(C4,作業用タブ1!$D$2:$F$27,3,FALSE),IF($D$1="LIFE+",VLOOKUP(C4,作業用タブ1!$D$33:$F$58,3,FALSE),IF($D$1="LIFE",VLOOKUP(C4,作業用タブ1!$D$64:$F$89,3,FALSE),IF($D$1="BASE",VLOOKUP(C4,作業用タブ1!$D$95:$F$120,3,FALSE),IF($D$1="LIFE+（キャンペーン）",VLOOKUP(C4,作業用タブ1!$D$126:$F$151,3,FALSE),IF($D$1="LIFE（キャンペーン）",VLOOKUP(C4,作業用タブ1!$D$157:$F$182,3,FALSE))))))) -> 例）28坪の場合、30坪に対して2坪下がる 30,000円×28坪＝840,000円UP
A5: □ | B5: 3 | C5: 施工面積 | D5: =IF($D$1="LACIE",VLOOKUP(C5,作業用タブ1!$D$2:$F$27,2,FALSE),IF($D$1="LIFE+",VLOOKUP(C5,作業用タブ1!$D$33:$F$58,2,FALSE),IF($D$1="LIFE",VLOOKUP(C5,作業用タブ1!$D$64:$F$89,2,FALSE),IF($D$1="BASE",VLOOKUP(C5,作業用タブ1!$D$95:$F$120,2,FALSE),IF($D$1="LIFE+（キャンペーン）",VLOOKUP(C5,作業用タブ1!$D$126:$F$151,2,FALSE),IF($D$1="LIFE（キャンペーン）",VLOOKUP(C5,作業用タブ1!$D$157:$F$182,2,FALSE))))))) -> 建物価格は「施工面積 × 坪単価」にて算出します。 施工面積は、延床面積に加え、外壁に三方を囲まれたビルトインガレージ、半ビルトインガレージを含み、当社基準により算出します。 また、以下の工事は、施工面積に含まれていない場合でも、別途費用が加算されます。 ① 軒の出・オーバーハング工事 ：42,000円／㎡（税別） ② 下屋工事 ：30,000円／㎡（税別） ③ バルコニー工事・吹抜工事 ：60,000円／㎡（税別） ※対象となる面積は、設計図書に基づき当社が算出します。 | F5: =IF($D$1="LACIE",VLOOKUP(C5,作業用タブ1!$D$2:$F$27,3,FALSE),IF($D$1="LIFE+",VLOOKUP(C5,作業用タブ1!$D$33:$F$58,3,FALSE),IF($D$1="LIFE",VLOOKUP(C5,作業用タブ1!$D$64:$F$89,3,FALSE),IF($D$1="BASE",VLOOKUP(C5,作業用タブ1!$D$95:$F$120,3,FALSE),IF($D$1="LIFE+（キャンペーン）",VLOOKUP(C5,作業用タブ1!$D$126:$F$151,3,FALSE),IF($D$1="LIFE（キャンペーン）",VLOOKUP(C5,作業用タブ1!$D$157:$F$182,3,FALSE))))))) -> 左記内容の対象となる面積については別紙1の参考写真をご確認下さい。
A6: □ | B6: 4 | C6: 住宅ローン | D6: =IF($D$1="LACIE",VLOOKUP(C6,作業用タブ1!$D$2:$F$27,2,FALSE),IF($D$1="LIFE+",VLOOKUP(C6,作業用タブ1!$D$33:$F$58,2,FALSE),IF($D$1="LIFE",VLOOKUP(C6,作業用タブ1!$D$64:$F$89,2,FALSE),IF($D$1="BASE",VLOOKUP(C6,作業用タブ1!$D$95:$F$120,2,FALSE),IF($D$1="LIFE+（キャンペーン）",VLOOKUP(C6,作業用タブ1!$D$126:$F$151,2,FALSE),IF($D$1="LIFE（キャンペーン）",VLOOKUP(C6,作業用タブ1!$D$157:$F$182,2,FALSE))))))) -> 住宅ローンの手続きはお施主様自身でお願いします。 当社でしかご用意ができない書類や図面等はお渡しします。 | F6: =IF($D$1="LACIE",VLOOKUP(C6,作業用タブ1!$D$2:$F$27,3,FALSE),IF($D$1="LIFE+",VLOOKUP(C6,作業用タブ1!$D$33:$F$58,3,FALSE),IF($D$1="LIFE",VLOOKUP(C6,作業用タブ1!$D$64:$F$89,3,FALSE),IF($D$1="BASE",VLOOKUP(C6,作業用タブ1!$D$95:$F$120,3,FALSE),IF($D$1="LIFE+（キャンペーン）",VLOOKUP(C6,作業用タブ1!$D$126:$F$151,3,FALSE),IF($D$1="LIFE（キャンペーン）",VLOOKUP(C6,作業用タブ1!$D$157:$F$182,3,FALSE))))))) -> ※事前審査も同様
A7: □ | B7: 5 | C7: =IF(OR($D$1="LIFE+（キャンペーン）",$D$1="LIFE（キャンペーン）"),"キャンペーン適応","打ち合わせ 期間") -> 打ち合わせ 期間 | D7: =IF($D$1="LACIE",VLOOKUP(C7,作業用タブ1!$D$2:$F$27,2,FALSE),IF($D$1="LIFE+",VLOOKUP(C7,作業用タブ1!$D$33:$F$58,2,FALSE),IF($D$1="LIFE",VLOOKUP(C7,作業用タブ1!$D$64:$F$89,2,FALSE),IF($D$1="BASE",VLOOKUP(C7,作業用タブ1!$D$95:$F$120,2,FALSE),IF($D$1="LIFE+（キャンペーン）",VLOOKUP(C7,作業用タブ1!$D$126:$F$151,2,FALSE),IF($D$1="LIFE（キャンペーン）",VLOOKUP(C7,作業用タブ1!$D$157:$F$182,2,FALSE))))))) -> 最大3ヵ月間 (回数：6回) | F7: =IF($D$1="LACIE",VLOOKUP(C7,作業用タブ1!$D$2:$F$27,3,FALSE),IF($D$1="LIFE+",VLOOKUP(C7,作業用タブ1!$D$33:$F$58,3,FALSE),IF($D$1="LIFE",VLOOKUP(C7,作業用タブ1!$D$64:$F$89,3,FALSE),IF($D$1="BASE",VLOOKUP(C7,作業用タブ1!$D$95:$F$120,3,FALSE),IF($D$1="LIFE+（キャンペーン）",VLOOKUP(C7,作業用タブ1!$D$126:$F$151,3,FALSE),IF($D$1="LIFE（キャンペーン）",VLOOKUP(C7,作業用タブ1!$D$157:$F$182,3,FALSE))))))) -> 打ち合わせ回数6回以下で下記の特典があります。 6回：★10万円相当 5回：★★20万円相当 ※初回ヒアリングは除く
A8: □ | B8: 6 | C8: 仕様 | D8: =IF($D$1="LACIE",VLOOKUP(C8,作業用タブ1!$D$2:$F$27,2,FALSE),IF($D$1="LIFE+",VLOOKUP(C8,作業用タブ1!$D$33:$F$58,2,FALSE),IF($D$1="LIFE",VLOOKUP(C8,作業用タブ1!$D$64:$F$89,2,FALSE),IF($D$1="BASE",VLOOKUP(C8,作業用タブ1!$D$95:$F$120,2,FALSE),IF($D$1="LIFE+（キャンペーン）",VLOOKUP(C8,作業用タブ1!$D$126:$F$151,2,FALSE),IF($D$1="LIFE（キャンペーン）",VLOOKUP(C8,作業用タブ1!$D$157:$F$182,2,FALSE))))))) -> セミオーダー制 当社の設計士がこだわり抜いた【 STYLE BOOK 】からのみ選択できます。 | F8: =(IF($D$1="LACIE",VLOOKUP(C8,作業用タブ1!$D$2:$F$27,3,FALSE),IF($D$1="LIFE+",VLOOKUP(C8,作業用タブ1!$D$33:$F$58,3,FALSE),IF($D$1="LIFE",VLOOKUP(C8,作業用タブ1!$D$64:$F$89,3,FALSE),IF($D$1="BASE",VLOOKUP(C8,作業用タブ1!$D$95:$F$120,3,FALSE),IF($D$1="LIFE+（キャンペーン）",VLOOKUP(C8,作業用タブ1!$D$126:$F$151,3,FALSE),IF($D$1="LIFE（キャンペーン）",VLOOKUP(C8,作業用タブ1!$D$157:$F$182,3,FALSE))))))))
A9: □ | B9: 7 | C9: 長期優良住宅 | D9: =IF($D$1="LACIE",VLOOKUP(C9,作業用タブ1!$D$2:$F$27,2,FALSE),IF($D$1="LIFE+",VLOOKUP(C9,作業用タブ1!$D$33:$F$58,2,FALSE),IF($D$1="LIFE",VLOOKUP(C9,作業用タブ1!$D$64:$F$89,2,FALSE),IF($D$1="BASE",VLOOKUP(C9,作業用タブ1!$D$95:$F$120,2,FALSE),IF($D$1="LIFE+（キャンペーン）",VLOOKUP(C9,作業用タブ1!$D$126:$F$151,2,FALSE),IF($D$1="LIFE（キャンペーン）",VLOOKUP(C9,作業用タブ1!$D$157:$F$182,2,FALSE))))))) -> 認定基準として、少なくとも1の階の床面積(階段部分を除く)が40㎡以上かつ床面積の合計75㎡必要です。 また、都市計画法第53条許可の対象となる地域では認定対象外です。 | F9: =IF($D$1="LACIE",VLOOKUP(C9,作業用タブ1!$D$2:$F$27,3,FALSE),IF($D$1="LIFE+",VLOOKUP(C9,作業用タブ1!$D$33:$F$58,3,FALSE),IF($D$1="LIFE",VLOOKUP(C9,作業用タブ1!$D$64:$F$89,3,FALSE),IF($D$1="BASE",VLOOKUP(C9,作業用タブ1!$D$95:$F$120,3,FALSE),IF($D$1="LIFE+（キャンペーン）",VLOOKUP(C9,作業用タブ1!$D$126:$F$151,3,FALSE),IF($D$1="LIFE（キャンペーン）",VLOOKUP(C9,作業用タブ1!$D$157:$F$182,3,FALSE))))))) -> 詳細は設計打ち合わせにてご確認ください。
A10: □ | B10: 8 | C10: Ua値 | D10: =IF($D$1="LACIE",VLOOKUP(C10,作業用タブ1!$D$2:$F$27,2,FALSE),IF($D$1="LIFE+",VLOOKUP(C10,作業用タブ1!$D$33:$F$58,2,FALSE),IF($D$1="LIFE",VLOOKUP(C10,作業用タブ1!$D$64:$F$89,2,FALSE),IF($D$1="BASE",VLOOKUP(C10,作業用タブ1!$D$95:$F$120,2,FALSE),IF($D$1="LIFE+（キャンペーン）",VLOOKUP(C10,作業用タブ1!$D$126:$F$151,2,FALSE),IF($D$1="LIFE（キャンペーン）",VLOOKUP(C10,作業用タブ1!$D$157:$F$182,2,FALSE))))))) -> 0.46W/㎡･Kを目安としております。但し、間取りや窓の個数･種類によって数値が変わり、0.46W/㎡･Kを確保できない場合があります。 | F10: =IF($D$1="LACIE",VLOOKUP(C10,作業用タブ1!$D$2:$F$27,3,FALSE),IF($D$1="LIFE+",VLOOKUP(C10,作業用タブ1!$D$33:$F$58,3,FALSE),IF($D$1="LIFE",VLOOKUP(C10,作業用タブ1!$D$64:$F$89,3,FALSE),IF($D$1="BASE",VLOOKUP(C10,作業用タブ1!$D$95:$F$120,3,FALSE),IF($D$1="LIFE+（キャンペーン）",VLOOKUP(C10,作業用タブ1!$D$126:$F$151,3,FALSE),IF($D$1="LIFE（キャンペーン）",VLOOKUP(C10,作業用タブ1!$D$157:$F$182,3,FALSE)))))))
A11: □ | B11: 9 | C11: 窓 | D11: =IF($D$1="LACIE",VLOOKUP(C11,作業用タブ1!$D$2:$F$27,2,FALSE),IF($D$1="LIFE+",VLOOKUP(C11,作業用タブ1!$D$33:$F$58,2,FALSE),IF($D$1="LIFE",VLOOKUP(C11,作業用タブ1!$D$64:$F$89,2,FALSE),IF($D$1="BASE",VLOOKUP(C11,作業用タブ1!$D$95:$F$120,2,FALSE),IF($D$1="LIFE+（キャンペーン）",VLOOKUP(C11,作業用タブ1!$D$126:$F$151,2,FALSE),IF($D$1="LIFE（キャンペーン）",VLOOKUP(C11,作業用タブ1!$D$157:$F$182,2,FALSE))))))) -> 施工面積が35坪未満12ヵ所、35～40坪13ヵ所、40～45坪14ヵ所、45～50坪15ヵ所、50坪以上16ヵ所までが標準個数です。 ※既製品のみ選定可能とし特注品の選択不可。 | F11: =IF($D$1="LACIE",VLOOKUP(C11,作業用タブ1!$D$2:$F$27,3,FALSE),IF($D$1="LIFE+",VLOOKUP(C11,作業用タブ1!$D$33:$F$58,3,FALSE),IF($D$1="LIFE",VLOOKUP(C11,作業用タブ1!$D$64:$F$89,3,FALSE),IF($D$1="BASE",VLOOKUP(C11,作業用タブ1!$D$95:$F$120,3,FALSE),IF($D$1="LIFE+（キャンペーン）",VLOOKUP(C11,作業用タブ1!$D$126:$F$151,3,FALSE),IF($D$1="LIFE（キャンペーン）",VLOOKUP(C11,作業用タブ1!$D$157:$F$182,3,FALSE))))))) -> 掃き出し窓(手動シャッター付)H2200は2ヵ所まで
A12: □ | B12: 10 | C12: 建具 | D12: =IF($D$1="LACIE",VLOOKUP(C12,作業用タブ1!$D$2:$F$27,2,FALSE),IF($D$1="LIFE+",VLOOKUP(C12,作業用タブ1!$D$33:$F$58,2,FALSE),IF($D$1="LIFE",VLOOKUP(C12,作業用タブ1!$D$64:$F$89,2,FALSE),IF($D$1="BASE",VLOOKUP(C12,作業用タブ1!$D$95:$F$120,2,FALSE),IF($D$1="LIFE+（キャンペーン）",VLOOKUP(C12,作業用タブ1!$D$126:$F$151,2,FALSE),IF($D$1="LIFE（キャンペーン）",VLOOKUP(C12,作業用タブ1!$D$157:$F$182,2,FALSE))))))) -> 開き扉H2400㎜標準(各居室・トイレ・脱衣室・ランドリーそれぞれ1ヵ所ずつ) ※片引き戸2ヵ所まで標準 | F12: =IF($D$1="LACIE",VLOOKUP(C12,作業用タブ1!$D$2:$F$27,3,FALSE),IF($D$1="LIFE+",VLOOKUP(C12,作業用タブ1!$D$33:$F$58,3,FALSE),IF($D$1="LIFE",VLOOKUP(C12,作業用タブ1!$D$64:$F$89,3,FALSE),IF($D$1="BASE",VLOOKUP(C12,作業用タブ1!$D$95:$F$120,3,FALSE),IF($D$1="LIFE+（キャンペーン）",VLOOKUP(C12,作業用タブ1!$D$126:$F$151,3,FALSE),IF($D$1="LIFE（キャンペーン）",VLOOKUP(C12,作業用タブ1!$D$157:$F$182,3,FALSE))))))) -> 引き戸3枚目以上及び収納扉等、リビング・書斎・洗面室・ファミリーCL・その他の部屋はオプションです。
A13: □ | B13: 11 | C13: 床材 | D13: =IF($D$1="LACIE",VLOOKUP(C13,作業用タブ1!$D$2:$F$27,2,FALSE),IF($D$1="LIFE+",VLOOKUP(C13,作業用タブ1!$D$33:$F$58,2,FALSE),IF($D$1="LIFE",VLOOKUP(C13,作業用タブ1!$D$64:$F$89,2,FALSE),IF($D$1="BASE",VLOOKUP(C13,作業用タブ1!$D$95:$F$120,2,FALSE),IF($D$1="LIFE+（キャンペーン）",VLOOKUP(C13,作業用タブ1!$D$126:$F$151,2,FALSE),IF($D$1="LIFE（キャンペーン）",VLOOKUP(C13,作業用タブ1!$D$157:$F$182,2,FALSE))))))) -> 無垢床材を使用した場合、伸縮、床鳴り、及び経年劣化による変色が発生 する場合があります。
A14: □ | B14: 12 | C14: 換気システム | D14: =IF($D$1="LACIE",VLOOKUP(C14,作業用タブ1!$D$2:$F$27,2,FALSE),IF($D$1="LIFE+",VLOOKUP(C14,作業用タブ1!$D$33:$F$58,2,FALSE),IF($D$1="LIFE",VLOOKUP(C14,作業用タブ1!$D$64:$F$89,2,FALSE),IF($D$1="BASE",VLOOKUP(C14,作業用タブ1!$D$95:$F$120,2,FALSE),IF($D$1="LIFE+（キャンペーン）",VLOOKUP(C14,作業用タブ1!$D$126:$F$151,2,FALSE),IF($D$1="LIFE（キャンペーン）",VLOOKUP(C14,作業用タブ1!$D$157:$F$182,2,FALSE))))))) -> 換気システムは全熱交換型第一種換気システム(Panasonic)が標準です。 | F14: =IF($D$1="LACIE",VLOOKUP(C14,作業用タブ1!$D$2:$F$27,3,FALSE),IF($D$1="LIFE+",VLOOKUP(C14,作業用タブ1!$D$33:$F$58,3,FALSE),IF($D$1="LIFE",VLOOKUP(C14,作業用タブ1!$D$64:$F$89,3,FALSE),IF($D$1="BASE",VLOOKUP(C14,作業用タブ1!$D$95:$F$120,3,FALSE),IF($D$1="LIFE+（キャンペーン）",VLOOKUP(C14,作業用タブ1!$D$126:$F$151,3,FALSE),IF($D$1="LIFE（キャンペーン）",VLOOKUP(C14,作業用タブ1!$D$157:$F$182,3,FALSE))))))) -> DSDD換気システム(okatomi)はオプションとなり、請負契約までに確定が必要です。請負契約後は変更できません。
A15: □ | B15: 13 | C15: ユニットバス | D15: =IF($D$1="LACIE",VLOOKUP(C15,作業用タブ1!$D$2:$F$27,2,FALSE),IF($D$1="LIFE+",VLOOKUP(C15,作業用タブ1!$D$33:$F$58,2,FALSE),IF($D$1="LIFE",VLOOKUP(C15,作業用タブ1!$D$64:$F$89,2,FALSE),IF($D$1="BASE",VLOOKUP(C15,作業用タブ1!$D$95:$F$120,2,FALSE),IF($D$1="LIFE+（キャンペーン）",VLOOKUP(C15,作業用タブ1!$D$126:$F$151,2,FALSE),IF($D$1="LIFE（キャンペーン）",VLOOKUP(C15,作業用タブ1!$D$157:$F$182,2,FALSE))))))) -> 天井有り | F15: =IF($D$1="LACIE",VLOOKUP(C15,作業用タブ1!$D$2:$F$27,3,FALSE),IF($D$1="LIFE+",VLOOKUP(C15,作業用タブ1!$D$33:$F$58,3,FALSE),IF($D$1="LIFE",VLOOKUP(C15,作業用タブ1!$D$64:$F$89,3,FALSE),IF($D$1="BASE",VLOOKUP(C15,作業用タブ1!$D$95:$F$120,3,FALSE),IF($D$1="LIFE+（キャンペーン）",VLOOKUP(C15,作業用タブ1!$D$126:$F$151,3,FALSE),IF($D$1="LIFE（キャンペーン）",VLOOKUP(C15,作業用タブ1!$D$157:$F$182,3,FALSE))))))) -> 天井無しの施工はDSDD換気システムをオプションで採用される場合のみ対応可能です。ご選択いただけるメーカーが限られますのでご注意ください。
A16: □ | B16: 14 | C16: エコキュート タンク | D16: =IF($D$1="LACIE",VLOOKUP(C16,作業用タブ1!$D$2:$F$27,2,FALSE),IF($D$1="LIFE+",VLOOKUP(C16,作業用タブ1!$D$33:$F$58,2,FALSE),IF($D$1="LIFE",VLOOKUP(C16,作業用タブ1!$D$64:$F$89,2,FALSE),IF($D$1="BASE",VLOOKUP(C16,作業用タブ1!$D$95:$F$120,2,FALSE),IF($D$1="LIFE+（キャンペーン）",VLOOKUP(C16,作業用タブ1!$D$126:$F$151,2,FALSE),IF($D$1="LIFE（キャンペーン）",VLOOKUP(C16,作業用タブ1!$D$157:$F$182,2,FALSE))))))) -> 室外置き | F16: =IF($D$1="LACIE",VLOOKUP(C16,作業用タブ1!$D$2:$F$27,3,FALSE),IF($D$1="LIFE+",VLOOKUP(C16,作業用タブ1!$D$33:$F$58,3,FALSE),IF($D$1="LIFE",VLOOKUP(C16,作業用タブ1!$D$64:$F$89,3,FALSE),IF($D$1="BASE",VLOOKUP(C16,作業用タブ1!$D$95:$F$120,3,FALSE),IF($D$1="LIFE+（キャンペーン）",VLOOKUP(C16,作業用タブ1!$D$126:$F$151,3,FALSE),IF($D$1="LIFE（キャンペーン）",VLOOKUP(C16,作業用タブ1!$D$157:$F$182,3,FALSE))))))) -> 室内置きはオプションです。
A17: □ | B17: 15 | C17: 点検口 | D17: =IF($D$1="LACIE",VLOOKUP(C17,作業用タブ1!$D$2:$F$27,2,FALSE),IF($D$1="LIFE+",VLOOKUP(C17,作業用タブ1!$D$33:$F$58,2,FALSE),IF($D$1="LIFE",VLOOKUP(C17,作業用タブ1!$D$64:$F$89,2,FALSE),IF($D$1="BASE",VLOOKUP(C17,作業用タブ1!$D$95:$F$120,2,FALSE),IF($D$1="LIFE+（キャンペーン）",VLOOKUP(C17,作業用タブ1!$D$126:$F$151,2,FALSE),IF($D$1="LIFE（キャンペーン）",VLOOKUP(C17,作業用タブ1!$D$157:$F$182,2,FALSE))))))) -> 換気システムや配管の定期点検及び不具合が起きた場合に備えて1,2Fに必要な箇所に天井･床下点検口を3～4つ以上設置しています。 | F17: =IF($D$1="LACIE",VLOOKUP(C17,作業用タブ1!$D$2:$F$27,3,FALSE),IF($D$1="LIFE+",VLOOKUP(C17,作業用タブ1!$D$33:$F$58,3,FALSE),IF($D$1="LIFE",VLOOKUP(C17,作業用タブ1!$D$64:$F$89,3,FALSE),IF($D$1="BASE",VLOOKUP(C17,作業用タブ1!$D$95:$F$120,3,FALSE),IF($D$1="LIFE+（キャンペーン）",VLOOKUP(C17,作業用タブ1!$D$126:$F$151,3,FALSE),IF($D$1="LIFE（キャンペーン）",VLOOKUP(C17,作業用タブ1!$D$157:$F$182,3,FALSE))))))) -> 点検口の個数および位置については間取りプランにより変動します。
A18: □ | B18: 16 | C18: 大工工事 | D18: =IF($D$1="LACIE",VLOOKUP(C18,作業用タブ1!$D$2:$F$27,2,FALSE),IF($D$1="LIFE+",VLOOKUP(C18,作業用タブ1!$D$33:$F$58,2,FALSE),IF($D$1="LIFE",VLOOKUP(C18,作業用タブ1!$D$64:$F$89,2,FALSE),IF($D$1="BASE",VLOOKUP(C18,作業用タブ1!$D$95:$F$120,2,FALSE),IF($D$1="LIFE+（キャンペーン）",VLOOKUP(C18,作業用タブ1!$D$126:$F$151,2,FALSE),IF($D$1="LIFE（キャンペーン）",VLOOKUP(C18,作業用タブ1!$D$157:$F$182,2,FALSE))))))) -> 造作工事はSTYLE BOOKに記載の内容のみ対応しています。 | F18: =IF($D$1="LACIE",VLOOKUP(C18,作業用タブ1!$D$2:$F$27,3,FALSE),IF($D$1="LIFE+",VLOOKUP(C18,作業用タブ1!$D$33:$F$58,3,FALSE),IF($D$1="LIFE",VLOOKUP(C18,作業用タブ1!$D$64:$F$89,3,FALSE),IF($D$1="BASE",VLOOKUP(C18,作業用タブ1!$D$95:$F$120,3,FALSE),IF($D$1="LIFE+（キャンペーン）",VLOOKUP(C18,作業用タブ1!$D$126:$F$151,3,FALSE),IF($D$1="LIFE（キャンペーン）",VLOOKUP(C18,作業用タブ1!$D$157:$F$182,3,FALSE))))))) -> 記載無き内容については提携リフォーム会社様へご相談ください。
A19: □ | B19: 17 | C19: トラブル防止 | D19: =IF($D$1="LACIE",VLOOKUP(C19,作業用タブ1!$D$2:$F$27,2,FALSE),IF($D$1="LIFE+",VLOOKUP(C19,作業用タブ1!$D$33:$F$58,2,FALSE),IF($D$1="LIFE",VLOOKUP(C19,作業用タブ1!$D$64:$F$89,2,FALSE),IF($D$1="BASE",VLOOKUP(C19,作業用タブ1!$D$95:$F$120,2,FALSE),IF($D$1="LIFE+（キャンペーン）",VLOOKUP(C19,作業用タブ1!$D$126:$F$151,2,FALSE),IF($D$1="LIFE（キャンペーン）",VLOOKUP(C19,作業用タブ1!$D$157:$F$182,2,FALSE))))))) -> STYLE BOOKに掲載の商品は、告知無しで変更になる場合があります。 ※各メーカーの商品改定および更新が定期的に行われるため、 契約締結時に交付されたSTYLE BOOKの記載価格・内容が適用されます。 | F19: =IF($D$1="LACIE",VLOOKUP(C19,作業用タブ1!$D$2:$F$27,3,FALSE),IF($D$1="LIFE+",VLOOKUP(C19,作業用タブ1!$D$33:$F$58,3,FALSE),IF($D$1="LIFE",VLOOKUP(C19,作業用タブ1!$D$64:$F$89,3,FALSE),IF($D$1="BASE",VLOOKUP(C19,作業用タブ1!$D$95:$F$120,3,FALSE),IF($D$1="LIFE+（キャンペーン）",VLOOKUP(C19,作業用タブ1!$D$126:$F$151,3,FALSE),IF($D$1="LIFE（キャンペーン）",VLOOKUP(C19,作業用タブ1!$D$157:$F$182,3,FALSE))))))) -> 打ち合わせ中に選定商品が廃番になることもありますのでご注意ください。 SNS等へのデータのUPはご遠慮ください。
A20: □ | B20: 18 | C20: オプション | D20: =IF($D$1="LACIE",VLOOKUP(C20,作業用タブ1!$D$2:$F$27,2,FALSE),IF($D$1="LIFE+",VLOOKUP(C20,作業用タブ1!$D$33:$F$58,2,FALSE),IF($D$1="LIFE",VLOOKUP(C20,作業用タブ1!$D$64:$F$89,2,FALSE),IF($D$1="BASE",VLOOKUP(C20,作業用タブ1!$D$95:$F$120,2,FALSE),IF($D$1="LIFE+（キャンペーン）",VLOOKUP(C20,作業用タブ1!$D$126:$F$151,2,FALSE),IF($D$1="LIFE（キャンペーン）",VLOOKUP(C20,作業用タブ1!$D$157:$F$182,2,FALSE))))))) -> 標準仕様の一部をやめることによる減額(＝マイナスオプション)は対応不可です。 | F20: =IF($D$1="LACIE",VLOOKUP(C20,作業用タブ1!$D$2:$F$27,3,FALSE),IF($D$1="LIFE+",VLOOKUP(C20,作業用タブ1!$D$33:$F$58,3,FALSE),IF($D$1="LIFE",VLOOKUP(C20,作業用タブ1!$D$64:$F$89,3,FALSE),IF($D$1="BASE",VLOOKUP(C20,作業用タブ1!$D$95:$F$120,3,FALSE),IF($D$1="LIFE+（キャンペーン）",VLOOKUP(C20,作業用タブ1!$D$126:$F$151,3,FALSE),IF($D$1="LIFE（キャンペーン）",VLOOKUP(C20,作業用タブ1!$D$157:$F$182,3,FALSE)))))))
A21: □ | B21: 19 | C21: 式典 | D21: =IF($D$1="LACIE",VLOOKUP(C21,作業用タブ1!$D$2:$F$27,2,FALSE),IF($D$1="LIFE+",VLOOKUP(C21,作業用タブ1!$D$33:$F$58,2,FALSE),IF($D$1="LIFE",VLOOKUP(C21,作業用タブ1!$D$64:$F$89,2,FALSE),IF($D$1="BASE",VLOOKUP(C21,作業用タブ1!$D$95:$F$120,2,FALSE),IF($D$1="LIFE+（キャンペーン）",VLOOKUP(C21,作業用タブ1!$D$126:$F$151,2,FALSE),IF($D$1="LIFE（キャンペーン）",VLOOKUP(C21,作業用タブ1!$D$157:$F$182,2,FALSE))))))) -> 地鎮祭および上棟式は省略しています。 | F21: =IF($D$1="LACIE",VLOOKUP(C21,作業用タブ1!$D$2:$F$27,3,FALSE),IF($D$1="LIFE+",VLOOKUP(C21,作業用タブ1!$D$33:$F$58,3,FALSE),IF($D$1="LIFE",VLOOKUP(C21,作業用タブ1!$D$64:$F$89,3,FALSE),IF($D$1="BASE",VLOOKUP(C21,作業用タブ1!$D$95:$F$120,3,FALSE),IF($D$1="LIFE+（キャンペーン）",VLOOKUP(C21,作業用タブ1!$D$126:$F$151,3,FALSE),IF($D$1="LIFE（キャンペーン）",VLOOKUP(C21,作業用タブ1!$D$157:$F$182,3,FALSE))))))) -> ご希望の方は鎮め物や上棟札を着工の2週間前までに担当者にお預けください。
A22: □ | B22: 20 | C22: 施工会社 | D22: =IF($D$1="LACIE",VLOOKUP(C22,作業用タブ1!$D$2:$F$27,2,FALSE),IF($D$1="LIFE+",VLOOKUP(C22,作業用タブ1!$D$33:$F$58,2,FALSE),IF($D$1="LIFE",VLOOKUP(C22,作業用タブ1!$D$64:$F$89,2,FALSE),IF($D$1="BASE",VLOOKUP(C22,作業用タブ1!$D$95:$F$120,2,FALSE),IF($D$1="LIFE+（キャンペーン）",VLOOKUP(C22,作業用タブ1!$D$126:$F$151,2,FALSE),IF($D$1="LIFE（キャンペーン）",VLOOKUP(C22,作業用タブ1!$D$157:$F$182,2,FALSE))))))) -> 施工については協力会社に委託する場合があります(協力会社は当社指定の一定の施工技術の基準を超えた会社)。 | F22: =IF($D$1="LACIE",VLOOKUP(C22,作業用タブ1!$D$2:$F$27,3,FALSE),IF($D$1="LIFE+",VLOOKUP(C22,作業用タブ1!$D$33:$F$58,3,FALSE),IF($D$1="LIFE",VLOOKUP(C22,作業用タブ1!$D$64:$F$89,3,FALSE),IF($D$1="BASE",VLOOKUP(C22,作業用タブ1!$D$95:$F$120,3,FALSE),IF($D$1="LIFE+（キャンペーン）",VLOOKUP(C22,作業用タブ1!$D$126:$F$151,3,FALSE),IF($D$1="LIFE（キャンペーン）",VLOOKUP(C22,作業用タブ1!$D$157:$F$182,3,FALSE)))))))
A23: □ | B23: 21 | C23: 撮影協力 | D23: =IF($D$1="LACIE",VLOOKUP(C23,作業用タブ1!$D$2:$F$27,2,FALSE),IF($D$1="LIFE+",VLOOKUP(C23,作業用タブ1!$D$33:$F$58,2,FALSE),IF($D$1="LIFE",VLOOKUP(C23,作業用タブ1!$D$64:$F$89,2,FALSE),IF($D$1="BASE",VLOOKUP(C23,作業用タブ1!$D$95:$F$120,2,FALSE),IF($D$1="LIFE+（キャンペーン）",VLOOKUP(C23,作業用タブ1!$D$126:$F$151,2,FALSE),IF($D$1="LIFE（キャンペーン）",VLOOKUP(C23,作業用タブ1!$D$157:$F$182,2,FALSE))))))) -> 広告媒体（紙面・WEB・SNSなど）への利用を目的とした撮影依頼をする場合がございます。ご協力お願いいたします。 | F23: =IF($D$1="LACIE",VLOOKUP(C23,作業用タブ1!$D$2:$F$27,3,FALSE),IF($D$1="LIFE+",VLOOKUP(C23,作業用タブ1!$D$33:$F$58,3,FALSE),IF($D$1="LIFE",VLOOKUP(C23,作業用タブ1!$D$64:$F$89,3,FALSE),IF($D$1="BASE",VLOOKUP(C23,作業用タブ1!$D$95:$F$120,3,FALSE),IF($D$1="LIFE+（キャンペーン）",VLOOKUP(C23,作業用タブ1!$D$126:$F$151,3,FALSE),IF($D$1="LIFE（キャンペーン）",VLOOKUP(C23,作業用タブ1!$D$157:$F$182,3,FALSE)))))))
A24: □ | B24: 22 | C24: お引渡し | D24: =IF($D$1="LACIE",VLOOKUP(C24,作業用タブ1!$D$2:$F$27,2,FALSE),IF($D$1="LIFE+",VLOOKUP(C24,作業用タブ1!$D$33:$F$58,2,FALSE),IF($D$1="LIFE",VLOOKUP(C24,作業用タブ1!$D$64:$F$89,2,FALSE),IF($D$1="BASE",VLOOKUP(C24,作業用タブ1!$D$95:$F$120,2,FALSE),IF($D$1="LIFE+（キャンペーン）",VLOOKUP(C24,作業用タブ1!$D$126:$F$151,2,FALSE),IF($D$1="LIFE（キャンペーン）",VLOOKUP(C24,作業用タブ1!$D$157:$F$182,2,FALSE))))))) -> 建物の残代金の全額お支払いを確認後、鍵をお渡しします。 外構工事の完成に関わらず、お支払いをお願いいたします。 | F24: =IF($D$1="LACIE",VLOOKUP(C24,作業用タブ1!$D$2:$F$27,3,FALSE),IF($D$1="LIFE+",VLOOKUP(C24,作業用タブ1!$D$33:$F$58,3,FALSE),IF($D$1="LIFE",VLOOKUP(C24,作業用タブ1!$D$64:$F$89,3,FALSE),IF($D$1="BASE",VLOOKUP(C24,作業用タブ1!$D$95:$F$120,3,FALSE),IF($D$1="LIFE+（キャンペーン）",VLOOKUP(C24,作業用タブ1!$D$126:$F$151,3,FALSE),IF($D$1="LIFE（キャンペーン）",VLOOKUP(C24,作業用タブ1!$D$157:$F$182,3,FALSE))))))) -> 外構工事をGハウス外構事業部GRAN GARDENにてご契約の方は、引渡し前に着工する場合がございます。GRAN GARDEN以外の業者様による外構工事については、責任の所在が不明確となる可能性があるため、建物のお引渡し後の着工とさせていただきます。
A25: □ | B25: 23 | C25: お引越し | D25: =IF($D$1="LACIE",VLOOKUP(C25,作業用タブ1!$D$2:$F$27,2,FALSE),IF($D$1="LIFE+",VLOOKUP(C25,作業用タブ1!$D$33:$F$58,2,FALSE),IF($D$1="LIFE",VLOOKUP(C25,作業用タブ1!$D$64:$F$89,2,FALSE),IF($D$1="BASE",VLOOKUP(C25,作業用タブ1!$D$95:$F$120,2,FALSE),IF($D$1="LIFE+（キャンペーン）",VLOOKUP(C25,作業用タブ1!$D$126:$F$151,2,FALSE),IF($D$1="LIFE（キャンペーン）",VLOOKUP(C25,作業用タブ1!$D$157:$F$182,2,FALSE))))))) -> お引越しにあたり、階段手摺の取り外しおよび設置が必要となる場合は別途25,000円(税別)発生します。 | F25: =IF($D$1="LACIE",VLOOKUP(C25,作業用タブ1!$D$2:$F$27,3,FALSE),IF($D$1="LIFE+",VLOOKUP(C25,作業用タブ1!$D$33:$F$58,3,FALSE),IF($D$1="LIFE",VLOOKUP(C25,作業用タブ1!$D$64:$F$89,3,FALSE),IF($D$1="BASE",VLOOKUP(C25,作業用タブ1!$D$95:$F$120,3,FALSE),IF($D$1="LIFE+（キャンペーン）",VLOOKUP(C25,作業用タブ1!$D$126:$F$151,3,FALSE),IF($D$1="LIFE（キャンペーン）",VLOOKUP(C25,作業用タブ1!$D$157:$F$182,3,FALSE))))))) -> お引越しに伴い必要となる工事は別途費用が発生します。
... A27: □ | B27: 25 | C27: LINE メール | D27: =IF($D$1="LACIE",VLOOKUP(C27,作業用タブ1!$D$2:$F$27,2,FALSE),IF($D$1="LIFE+",VLOOKUP(C27,作業用タブ1!$D$33:$F$58,2,FALSE),IF($D$1="LIFE",VLOOKUP(C27,作業用タブ1!$D$64:$F$89,2,FALSE),IF($D$1="BASE",VLOOKUP(C27,作業用タブ1!$D$95:$F$120,2,FALSE),IF($D$1="LIFE+（キャンペーン）",VLOOKUP(C27,作業用タブ1!$D$126:$F$151,2,FALSE),IF($D$1="LIFE（キャンペーン）",VLOOKUP(C27,作業用タブ1!$D$157:$F$182,2,FALSE))))))) -> 間違い防止のため、設計･コーディネーター担当へのご要望･ご質問等、ご相談内容をLINEやメールにてお伝えいただくことをお断りしております。打ち合わせの際にまとめて担当者にご相談いただくようにご協力お願いします。 | F27: =IF($D$1="LACIE",VLOOKUP(C27,作業用タブ1!$D$2:$F$27,3,FALSE),IF($D$1="LIFE+",VLOOKUP(C27,作業用タブ1!$D$33:$F$58,3,FALSE),IF($D$1="LIFE",VLOOKUP(C27,作業用タブ1!$D$64:$F$89,3,FALSE),IF($D$1="BASE",VLOOKUP(C27,作業用タブ1!$D$95:$F$120,3,FALSE),IF($D$1="LIFE+（キャンペーン）",VLOOKUP(C27,作業用タブ1!$D$126:$F$151,3,FALSE),IF($D$1="LIFE（キャンペーン）",VLOOKUP(C27,作業用タブ1!$D$157:$F$182,3,FALSE)))))))
E29: 住所 | F29: =初期入力!B5 -> 0
E31: 氏名 | F31: =初期入力!B4 -> 0 | G31: 印
E33: 住所 | F33: =IF(初期入力!B7="","",初期入力!B7)
E35: 氏名 | F35: =IF(初期入力!B6="","",初期入力!B6) | G35: 印

Sheet 作業用タブ1
A1: LACIE | J1: 【商品を選択】
D2: 項目 | E2: 標準内容 | F2: 備考 | J2: LACIE
B3: □ | C3: 1 | D3: 間取り | E3: 完全自由設計 ※4マス×910mm間隔に柱または壁の設置が必要です。 | F3: 申請業務に進んでいくため、基本設計確定後の変更は出来ません。 | J3: LIFE+
B4: □ | C4: 2 | D4: 坪単価 | E4: 本体工事価格は 70万円(税別) 30坪未満の場合割増計算となり、1坪下がる度に15,000円×坪数＝追加費用が発生します。 3階建ての場合は坪単価＋40,000円UP 下屋の場合は下屋部分㎡×30,000円UP | F4: 例) 28坪の場合、30坪に対して2坪下がる 30,000円×28坪＝840,000円UP | J4: LIFE
B5: □ | C5: 3 | D5: 施工面積 | E5: 建物価格は「施工面積 × 坪単価」にて算出します。 施工面積は、延床面積に加え、外壁に三方を囲まれたビルトインガレージ、半ビルトインガレージを含み、当社基準により算出します。 また、以下の工事は、施工面積に含まれていない場合でも、別途費用が加算されます。 ① 軒の出・オーバーハング工事 ：42,000円／㎡（税別） ② 下屋工事 ：30,000円／㎡（税別） ③ バルコニー工事・吹抜工事 ：60,000円／㎡（税別） ※対象となる面積は、設計図書に基づき当社が算出します。 | F5: 左記内容の対象となる面積については別紙1の参考写真をご確認下さい。
B6: □ | C6: 4 | D6: 住宅ローン | E6: 住宅ローンの手続きはお施主様自身でお願いします。 当社でしかご用意ができない書類や図面等はお渡しします。 | F6: ※事前審査も同様 | J6: BASE
B7: □ | C7: 5 | D7: 打ち合わせ 期間 | E7: 最大3ヵ月間 (回数：6回) | F7: 打ち合わせ回数6回以下で下記の特典があります。 6回：★10万円相当 5回：★★20万円相当 ※初回ヒアリングは除く
B8: □ | C8: 6 | D8: 仕様 | E8: セミオーダー制 当社の設計士がこだわり抜いた【 STYLE BOOK 】からのみ選択できます。
B9: □ | C9: 7 | D9: 長期優良住宅 | E9: 認定基準として、少なくとも1の階の床面積(階段部分を除く)が40㎡以上かつ床面積の合計75㎡必要です。 また、都市計画法第53条許可の対象となる地域では認定対象外です。 | F9: 詳細は設計打ち合わせにてご確認ください。
B10: □ | C10: 8 | D10: Ua値 | E10: 0.46W/㎡･Kを目安としております。但し、間取りや窓の個数･種類によって数値が変わり、0.46W/㎡･Kを確保できない場合があります。
B11: □ | C11: 9 | D11: 窓 | E11: 施工面積が35坪未満12ヵ所、35～40坪13ヵ所、40～45坪14ヵ所、45～50坪15ヵ所、50坪以上16ヵ所までが標準個数です。 ※既製品のみ選定可能とし特注品の選択不可。 | F11: 掃き出し窓(手動シャッター付)H2200は2ヵ所まで
B12: □ | C12: 10 | D12: 建具 | E12: 開き扉H2400㎜標準(各居室・トイレ・脱衣室・ランドリーそれぞれ1ヵ所ずつ) ※片引き戸2ヵ所まで標準 | F12: 引き戸3枚目以上及び収納扉等、リビング・書斎・洗面室・ファミリーCL・その他の部屋はオプションです。
B13: □ | C13: 11 | D13: 床材 | E13: 無垢床材を使用した場合、伸縮、床鳴り、及び経年劣化による変色が発生 する場合があります。
B14: □ | C14: 12 | D14: 換気システム | E14: 換気システムは全熱交換型第一種換気システム(Panasonic)が標準です。 | F14: DSDD換気システム(okatomi)はオプションとなり、請負契約までに確定が必要です。請負契約後は変更できません。
B15: □ | C15: 13 | D15: ユニットバス | E15: 天井有り | F15: 天井無しの施工はDSDD換気システムをオプションで採用される場合のみ対応可能です。ご選択いただけるメーカーが限られますのでご注意ください。
B16: □ | C16: 14 | D16: エコキュート タンク | E16: 室外置き | F16: 室内置きはオプションです。
B17: □ | C17: 15 | D17: 点検口 | E17: 換気システムや配管の定期点検及び不具合が起きた場合に備えて1,2Fに必要な箇所に天井･床下点検口を3～4つ以上設置しています。 | F17: 点検口の個数および位置については間取りプランにより変動します。
B18: □ | C18: 16 | D18: 大工工事 | E18: 造作工事はSTYLE BOOKに記載の内容のみ対応しています。 | F18: 記載無き内容については提携リフォーム会社様へご相談ください。
B19: □ | C19: 17 | D19: トラブル防止 | E19: STYLE BOOKに掲載の商品は、告知無しで変更になる場合があります。 ※各メーカーの商品改定及び更新が定期的に行われるため、 契約締結時に交付されたSTYLE BOOKの記載価格・内容が適用されます。 | F19: 打ち合わせ中に選定商品が廃番になることもありますのでご注意ください。 SNS等へのデータのUPはご遠慮ください。
B20: □ | C20: 18 | D20: オプション | E20: 標準仕様の一部をやめることによる減額(＝マイナスオプション)は対応不可です。
B21: □ | C21: 19 | D21: 式典 | E21: 地鎮祭および上棟式は省略しています。 | F21: ご希望の方は鎮め物や上棟札を着工の2週間前までに担当者にお預けください。
B22: □ | C22: 20 | D22: 施工会社 | E22: 施工については協力会社に委託する場合があります(協力会社は当社指定の一定の施工技術の基準を超えた会社)。
B23: □ | C23: 21 | D23: 撮影協力 | E23: 広告媒体（紙面・WEB・SNSなど）への利用を目的とした撮影依頼をする場合がございます。ご協力お願いいたします。
B24: □ | C24: 22 | D24: お引渡し | E24: 建物の残代金の全額お支払いを確認後、鍵をお渡しします。 外構工事の完成に関わらず、お支払いをお願いいたします。 | F24: 外構工事をGハウス外構事業部GRAN GARDENにてご契約の方は、引渡し前に着工する場合がございます。GRAN GARDEN以外の業者様による外構工事については、責任の所在が不明確となる可能性があるため、建物のお引渡し後の着工とさせていただきます。
B25: □ | C25: 23 | D25: お引越し | E25: お引越しにあたり、階段手摺の取り外しおよび設置が必要となる場合は別途25,000円(税別)発生します。 | F25: お引越しに伴い必要となる工事は別途費用が発生します。
B26: □ | C26: 24 | D26: 補助金 | E26: 補助金の手続きはお施主様自身でお願いします。 | F26: ※当社で代理申請する場合は別途費用が発生します。 ZEH補助金はGハウスの行程では対応不可です。
B27: □ | C27: 25 | D27: LINE メール | E27: 間違い防止のため、設計･コーディネーター担当へのご要望･ご質問等、ご相談内容をLINEやメールにてお伝えいただくことをお断りしております。打ち合わせの際にまとめて担当者にご相談いただくようにご協力お願いします。
A32: LIFE+
D33: 項目 | E33: 標準内容 | F33: 備考
B34: □ | C34: 1 | D34: 間取り | E34: 完全自由設計 ※4マス×910mm間隔に柱または壁の設置が必要です。 | F34: 申請業務に進んでいくため、基本設計確定後の変更は出来ません。
B35: □ | C35: 2 | D35: 坪単価 | E35: 本体工事価格は 63万円(税別) 30坪未満の場合割増計算となり、1坪下がる度に15,000円×坪数＝追加費用が発生します。 3階建ての場合は坪単価＋40,000円UP 下屋の場合は下屋部分㎡×30,000円UP | F35: 例）28坪の場合、30坪に対して2坪下がる 30,000円×28坪＝840,000円UP
B36: □ | C36: 3 | D36: 施工面積 | E36: 建物価格は「施工面積 × 坪単価」にて算出します。 施工面積は、延床面積に加え、外壁に三方を囲まれたビルトインガレージ、半ビルトインガレージを含み、当社基準により算出します。 また、以下の工事は、施工面積に含まれていない場合でも、別途費用が加算されます。 ① 軒の出・オーバーハング工事 ：42,000円／㎡（税別） ② 下屋工事 ：30,000円／㎡（税別） ③ バルコニー工事・吹抜工事 ：60,000円／㎡（税別） ※対象となる面積は、設計図書に基づき当社が算出します。 | F36: 左記内容の対象となる面積については別紙1の参考写真をご確認下さい。
B37: □ | C37: 4 | D37: 住宅ローン | E37: 住宅ローンの手続きはお施主様自身でお願いします。 当社でしかご用意ができない書類や図面等はお渡しします。 | F37: ※事前審査も同様
B38: □ | C38: 5 | D38: 打ち合わせ 期間 | E38: 最大3ヵ月間 (回数：6回) | F38: 打ち合わせ回数6回以下で下記の特典があります。 6回：★10万円相当 5回：★★20万円相当 ※初回ヒアリングは除く
B39: □ | C39: 6 | D39: 仕様 | E39: セミオーダー制 当社の設計士がこだわり抜いた【 STYLE BOOK 】からのみ選択できます。
B40: □ | C40: 7 | D40: 長期優良住宅 | E40: 認定基準として、少なくとも1の階の床面積(階段部分を除く)が40㎡以上かつ床面積の合計75㎡必要です。 また、都市計画法第53条許可の対象となる地域では認定対象外です。 | F40: 詳細は設計打ち合わせにてご確認ください。
B41: □ | C41: 8 | D41: Ua値 | E41: 0.46W/㎡･Kを目安としております。但し、間取りや窓の個数･種類によって数値が変わり、0.46W/㎡･Kを確保できない場合があります。
B42: □ | C42: 9 | D42: 窓 | E42: 施工面積が35坪未満12ヵ所、35～40坪13ヵ所、40～45坪14ヵ所、45～50坪15ヵ所、50坪以上16ヵ所までが標準個数です。 ※既製品のみ選定可能とし特注品の選択不可。 | F42: 掃き出し窓(手動シャッター付)H2200は2ヵ所まで
B43: □ | C43: 10 | D43: 建具 | E43: 開き扉H2400㎜標準(各居室・トイレ・脱衣室・ランドリーそれぞれ1ヵ所ずつ) ※片引き戸2ヵ所まで標準 | F43: 引き戸3枚目以上及び収納扉等、リビング・書斎・洗面室・ファミリーCL・その他の部屋はオプションです。
B44: □ | C44: 11 | D44: 床材 | E44: 無垢床材を使用した場合、伸縮、床鳴り、及び経年劣化による変色が発生 する場合があります。
...

Sheet LIFE,LIFE+キャンペーン制約事項
D1: LIFE+（キャンペーン） | E1: の仕様 制約事項一覧 | I1: ←商品名タブにて選択必要
C2: 項目 | D2: 標準内容 | F2: 備考
A3: □ | B3: 1 | C3: 間取り | D3: =IF($D$1="LACIE",VLOOKUP(C3,#REF!,2,FALSE),IF($D$1="LIFE+",VLOOKUP(C3,#REF!,2,FALSE),IF($D$1="LIFE",VLOOKUP(C3,#REF!,2,FALSE),IF($D$1="BASE",VLOOKUP(C3,#REF!,2,FALSE),IF($D$1="LIFE+（キャンペーン）",VLOOKUP(C3,#REF!,2,FALSE),IF($D$1="LIFE（キャンペーン）",VLOOKUP(C3,#REF!,2,FALSE),IF($D$1="LIFE+（キャンペーン）",VLOOKUP(C3,#REF!,2,FALSE),IF($D$1="LIFE（キャンペーン）",VLOOKUP(C3,#REF!,2,FALSE))))))))) -> #REF! | F3: =IF($D$1="LACIE",VLOOKUP(C3,#REF!,3,FALSE),IF($D$1="LIFE+",VLOOKUP(C3,#REF!,3,FALSE),IF($D$1="LIFE",VLOOKUP(C3,#REF!,3,FALSE),IF($D$1="BASE",VLOOKUP(C3,#REF!,3,FALSE),IF($D$1="LIFE+（キャンペーン）",VLOOKUP(C3,#REF!,3,FALSE),IF($D$1="LIFE（キャンペーン）",VLOOKUP(C3,#REF!,3,FALSE))))))) -> #REF!
A4: □ | B4: 2 | C4: 坪単価 | D4: =IF($D$1="LACIE",VLOOKUP(C4,#REF!,2,FALSE),IF($D$1="LIFE+",VLOOKUP(C4,#REF!,2,FALSE),IF($D$1="LIFE",VLOOKUP(C4,#REF!,2,FALSE),IF($D$1="BASE",VLOOKUP(C4,#REF!,2,FALSE),IF($D$1="LIFE+（キャンペーン）",VLOOKUP(C4,#REF!,2,FALSE),IF($D$1="LIFE（キャンペーン）",VLOOKUP(C4,#REF!,2,FALSE))))))) -> #REF! | F4: =IF($D$1="LACIE",VLOOKUP(C4,#REF!,3,FALSE),IF($D$1="LIFE+",VLOOKUP(C4,#REF!,3,FALSE),IF($D$1="LIFE",VLOOKUP(C4,#REF!,3,FALSE),IF($D$1="BASE",VLOOKUP(C4,#REF!,3,FALSE),IF($D$1="LIFE+（キャンペーン）",VLOOKUP(C4,#REF!,3,FALSE),IF($D$1="LIFE（キャンペーン）",VLOOKUP(C4,#REF!,3,FALSE))))))) -> #REF!
A5: □ | B5: 3 | C5: 住宅ローン | D5: =IF($D$1="LACIE",VLOOKUP(C5,#REF!,2,FALSE),IF($D$1="LIFE+",VLOOKUP(C5,#REF!,2,FALSE),IF($D$1="LIFE",VLOOKUP(C5,#REF!,2,FALSE),IF($D$1="BASE",VLOOKUP(C5,#REF!,2,FALSE),IF($D$1="LIFE+（キャンペーン）",VLOOKUP(C5,#REF!,2,FALSE),IF($D$1="LIFE（キャンペーン）",VLOOKUP(C5,#REF!,2,FALSE))))))) -> #REF! | F5: =IF($D$1="LACIE",VLOOKUP(C5,#REF!,3,FALSE),IF($D$1="LIFE+",VLOOKUP(C5,#REF!,3,FALSE),IF($D$1="LIFE",VLOOKUP(C5,#REF!,3,FALSE),IF($D$1="BASE",VLOOKUP(C5,#REF!,3,FALSE),IF($D$1="LIFE+（キャンペーン）",VLOOKUP(C5,#REF!,3,FALSE),IF($D$1="LIFE（キャンペーン）",VLOOKUP(C5,#REF!,3,FALSE))))))) -> #REF!
A6: □ | B6: 4 | C6: =IF(OR($D$1="LIFE+（キャンペーン）",$D$1="LIFE（キャンペーン）"),"打ち合わせ 期間") -> 打ち合わせ 期間 | D6: =IF($D$1="LACIE",VLOOKUP(C6,#REF!,2,FALSE),IF($D$1="LIFE+",VLOOKUP(C6,#REF!,2,FALSE),IF($D$1="LIFE",VLOOKUP(C6,#REF!,2,FALSE),IF($D$1="BASE",VLOOKUP(C6,#REF!,2,FALSE),IF($D$1="LIFE+（キャンペーン）",VLOOKUP(C6,#REF!,2,FALSE),IF($D$1="LIFE（キャンペーン）",VLOOKUP(C6,#REF!,2,FALSE))))))) -> #REF! | F6: =IF($D$1="LACIE",VLOOKUP(C6,#REF!,3,FALSE),IF($D$1="LIFE+",VLOOKUP(C6,#REF!,3,FALSE),IF($D$1="LIFE",VLOOKUP(C6,#REF!,3,FALSE),IF($D$1="BASE",VLOOKUP(C6,#REF!,3,FALSE),IF($D$1="LIFE+（キャンペーン）",VLOOKUP(C6,#REF!,3,FALSE),IF($D$1="LIFE（キャンペーン）",VLOOKUP(C6,#REF!,3,FALSE))))))) -> #REF!
A7: □ | B7: 5 | C7: 仕様 | D7: =IF($D$1="LACIE",VLOOKUP(C7,#REF!,2,FALSE),IF($D$1="LIFE+",VLOOKUP(C7,#REF!,2,FALSE),IF($D$1="LIFE",VLOOKUP(C7,#REF!,2,FALSE),IF($D$1="BASE",VLOOKUP(C7,#REF!,2,FALSE),IF($D$1="LIFE+（キャンペーン）",VLOOKUP(C7,#REF!,2,FALSE),IF($D$1="LIFE（キャンペーン）",VLOOKUP(C7,#REF!,2,FALSE))))))) -> #REF! | F7: =(IF($D$1="LACIE",VLOOKUP(C7,#REF!,3,FALSE),IF($D$1="LIFE+",VLOOKUP(C7,#REF!,3,FALSE),IF($D$1="LIFE",VLOOKUP(C7,#REF!,3,FALSE),IF($D$1="BASE",VLOOKUP(C7,#REF!,3,FALSE),IF($D$1="LIFE+（キャンペーン）",VLOOKUP(C7,#REF!,3,FALSE),IF($D$1="LIFE（キャンペーン）",VLOOKUP(C7,#REF!,3,FALSE)))))))) -> #REF!
A8: □ | B8: 6 | C8: 長期優良住宅 | D8: =IF($D$1="LACIE",VLOOKUP(C8,#REF!,2,FALSE),IF($D$1="LIFE+",VLOOKUP(C8,#REF!,2,FALSE),IF($D$1="LIFE",VLOOKUP(C8,#REF!,2,FALSE),IF($D$1="BASE",VLOOKUP(C8,#REF!,2,FALSE),IF($D$1="LIFE+（キャンペーン）",VLOOKUP(C8,#REF!,2,FALSE),IF($D$1="LIFE（キャンペーン）",VLOOKUP(C8,#REF!,2,FALSE))))))) -> #REF! | F8: =IF($D$1="LACIE",VLOOKUP(C8,#REF!,3,FALSE),IF($D$1="LIFE+",VLOOKUP(C8,#REF!,3,FALSE),IF($D$1="LIFE",VLOOKUP(C8,#REF!,3,FALSE),IF($D$1="BASE",VLOOKUP(C8,#REF!,3,FALSE),IF($D$1="LIFE+（キャンペーン）",VLOOKUP(C8,#REF!,3,FALSE),IF($D$1="LIFE（キャンペーン）",VLOOKUP(C8,#REF!,3,FALSE))))))) -> #REF!
A9: □ | B9: 7 | C9: Ua値 | D9: =IF($D$1="LACIE",VLOOKUP(C9,#REF!,2,FALSE),IF($D$1="LIFE+",VLOOKUP(C9,#REF!,2,FALSE),IF($D$1="LIFE",VLOOKUP(C9,#REF!,2,FALSE),IF($D$1="BASE",VLOOKUP(C9,#REF!,2,FALSE),IF($D$1="LIFE+（キャンペーン）",VLOOKUP(C9,#REF!,2,FALSE),IF($D$1="LIFE（キャンペーン）",VLOOKUP(C9,#REF!,2,FALSE))))))) -> #REF! | F9: =IF($D$1="LACIE",VLOOKUP(C9,#REF!,3,FALSE),IF($D$1="LIFE+",VLOOKUP(C9,#REF!,3,FALSE),IF($D$1="LIFE",VLOOKUP(C9,#REF!,3,FALSE),IF($D$1="BASE",VLOOKUP(C9,#REF!,3,FALSE),IF($D$1="LIFE+（キャンペーン）",VLOOKUP(C9,#REF!,3,FALSE),IF($D$1="LIFE（キャンペーン）",VLOOKUP(C9,#REF!,3,FALSE))))))) -> #REF!
A10: □ | B10: 8 | C10: 窓 | D10: =IF($D$1="LACIE",VLOOKUP(C10,#REF!,2,FALSE),IF($D$1="LIFE+",VLOOKUP(C10,#REF!,2,FALSE),IF($D$1="LIFE",VLOOKUP(C10,#REF!,2,FALSE),IF($D$1="BASE",VLOOKUP(C10,#REF!,2,FALSE),IF($D$1="LIFE+（キャンペーン）",VLOOKUP(C10,#REF!,2,FALSE),IF($D$1="LIFE（キャンペーン）",VLOOKUP(C10,#REF!,2,FALSE))))))) -> #REF! | F10: =IF($D$1="LACIE",VLOOKUP(C10,#REF!,3,FALSE),IF($D$1="LIFE+",VLOOKUP(C10,#REF!,3,FALSE),IF($D$1="LIFE",VLOOKUP(C10,#REF!,3,FALSE),IF($D$1="BASE",VLOOKUP(C10,#REF!,3,FALSE),IF($D$1="LIFE+（キャンペーン）",VLOOKUP(C10,#REF!,3,FALSE),IF($D$1="LIFE（キャンペーン）",VLOOKUP(C10,#REF!,3,FALSE))))))) -> #REF!
A11: □ | B11: 9 | C11: 建具 | D11: =IF($D$1="LACIE",VLOOKUP(C11,#REF!,2,FALSE),IF($D$1="LIFE+",VLOOKUP(C11,#REF!,2,FALSE),IF($D$1="LIFE",VLOOKUP(C11,#REF!,2,FALSE),IF($D$1="BASE",VLOOKUP(C11,#REF!,2,FALSE),IF($D$1="LIFE+（キャンペーン）",VLOOKUP(C11,#REF!,2,FALSE),IF($D$1="LIFE（キャンペーン）",VLOOKUP(C11,#REF!,2,FALSE))))))) -> #REF! | F11: =IF($D$1="LACIE",VLOOKUP(C11,#REF!,3,FALSE),IF($D$1="LIFE+",VLOOKUP(C11,#REF!,3,FALSE),IF($D$1="LIFE",VLOOKUP(C11,#REF!,3,FALSE),IF($D$1="BASE",VLOOKUP(C11,#REF!,3,FALSE),IF($D$1="LIFE+（キャンペーン）",VLOOKUP(C11,#REF!,3,FALSE),IF($D$1="LIFE（キャンペーン）",VLOOKUP(C11,#REF!,3,FALSE))))))) -> #REF!
A12: □ | B12: 10 | C12: 床材 | D12: =IF($D$1="LACIE",VLOOKUP(C12,#REF!,2,FALSE),IF($D$1="LIFE+",VLOOKUP(C12,#REF!,2,FALSE),IF($D$1="LIFE",VLOOKUP(C12,#REF!,2,FALSE),IF($D$1="BASE",VLOOKUP(C12,#REF!,2,FALSE),IF($D$1="LIFE+（キャンペーン）",VLOOKUP(C12,#REF!,2,FALSE),IF($D$1="LIFE（キャンペーン）",VLOOKUP(C12,#REF!,2,FALSE))))))) -> #REF!
A13: □ | B13: 11 | C13: 換気システム | D13: =IF($D$1="LACIE",VLOOKUP(C13,#REF!,2,FALSE),IF($D$1="LIFE+",VLOOKUP(C13,#REF!,2,FALSE),IF($D$1="LIFE",VLOOKUP(C13,#REF!,2,FALSE),IF($D$1="BASE",VLOOKUP(C13,#REF!,2,FALSE),IF($D$1="LIFE+（キャンペーン）",VLOOKUP(C13,#REF!,2,FALSE),IF($D$1="LIFE（キャンペーン）",VLOOKUP(C13,#REF!,2,FALSE))))))) -> #REF! | F13: =IF($D$1="LACIE",VLOOKUP(C13,#REF!,3,FALSE),IF($D$1="LIFE+",VLOOKUP(C13,#REF!,3,FALSE),IF($D$1="LIFE",VLOOKUP(C13,#REF!,3,FALSE),IF($D$1="BASE",VLOOKUP(C13,#REF!,3,FALSE),IF($D$1="LIFE+（キャンペーン）",VLOOKUP(C13,#REF!,3,FALSE),IF($D$1="LIFE（キャンペーン）",VLOOKUP(C13,#REF!,3,FALSE))))))) -> #REF!
A14: □ | B14: 12 | C14: ユニットバス | D14: =IF($D$1="LACIE",VLOOKUP(C14,#REF!,2,FALSE),IF($D$1="LIFE+",VLOOKUP(C14,#REF!,2,FALSE),IF($D$1="LIFE",VLOOKUP(C14,#REF!,2,FALSE),IF($D$1="BASE",VLOOKUP(C14,#REF!,2,FALSE),IF($D$1="LIFE+（キャンペーン）",VLOOKUP(C14,#REF!,2,FALSE),IF($D$1="LIFE（キャンペーン）",VLOOKUP(C14,#REF!,2,FALSE))))))) -> #REF! | F14: =IF($D$1="LACIE",VLOOKUP(C14,#REF!,3,FALSE),IF($D$1="LIFE+",VLOOKUP(C14,#REF!,3,FALSE),IF($D$1="LIFE",VLOOKUP(C14,#REF!,3,FALSE),IF($D$1="BASE",VLOOKUP(C14,#REF!,3,FALSE),IF($D$1="LIFE+（キャンペーン）",VLOOKUP(C14,#REF!,3,FALSE),IF($D$1="LIFE（キャンペーン）",VLOOKUP(C14,#REF!,3,FALSE))))))) -> #REF!
A15: □ | B15: 13 | C15: エコキュート タンク | D15: =IF($D$1="LACIE",VLOOKUP(C15,#REF!,2,FALSE),IF($D$1="LIFE+",VLOOKUP(C15,#REF!,2,FALSE),IF($D$1="LIFE",VLOOKUP(C15,#REF!,2,FALSE),IF($D$1="BASE",VLOOKUP(C15,#REF!,2,FALSE),IF($D$1="LIFE+（キャンペーン）",VLOOKUP(C15,#REF!,2,FALSE),IF($D$1="LIFE（キャンペーン）",VLOOKUP(C15,#REF!,2,FALSE))))))) -> #REF! | F15: =IF($D$1="LACIE",VLOOKUP(C15,#REF!,3,FALSE),IF($D$1="LIFE+",VLOOKUP(C15,#REF!,3,FALSE),IF($D$1="LIFE",VLOOKUP(C15,#REF!,3,FALSE),IF($D$1="BASE",VLOOKUP(C15,#REF!,3,FALSE),IF($D$1="LIFE+（キャンペーン）",VLOOKUP(C15,#REF!,3,FALSE),IF($D$1="LIFE（キャンペーン）",VLOOKUP(C15,#REF!,3,FALSE))))))) -> #REF!
A16: □ | B16: 14 | C16: 点検口 | D16: =IF($D$1="LACIE",VLOOKUP(C16,#REF!,2,FALSE),IF($D$1="LIFE+",VLOOKUP(C16,#REF!,2,FALSE),IF($D$1="LIFE",VLOOKUP(C16,#REF!,2,FALSE),IF($D$1="BASE",VLOOKUP(C16,#REF!,2,FALSE),IF($D$1="LIFE+（キャンペーン）",VLOOKUP(C16,#REF!,2,FALSE),IF($D$1="LIFE（キャンペーン）",VLOOKUP(C16,#REF!,2,FALSE))))))) -> #REF! | F16: =IF($D$1="LACIE",VLOOKUP(C16,#REF!,3,FALSE),IF($D$1="LIFE+",VLOOKUP(C16,#REF!,3,FALSE),IF($D$1="LIFE",VLOOKUP(C16,#REF!,3,FALSE),IF($D$1="BASE",VLOOKUP(C16,#REF!,3,FALSE),IF($D$1="LIFE+（キャンペーン）",VLOOKUP(C16,#REF!,3,FALSE),IF($D$1="LIFE（キャンペーン）",VLOOKUP(C16,#REF!,3,FALSE))))))) -> #REF!
A17: □ | B17: 15 | C17: 大工工事 | D17: =IF($D$1="LACIE",VLOOKUP(C17,#REF!,2,FALSE),IF($D$1="LIFE+",VLOOKUP(C17,#REF!,2,FALSE),IF($D$1="LIFE",VLOOKUP(C17,#REF!,2,FALSE),IF($D$1="BASE",VLOOKUP(C17,#REF!,2,FALSE),IF($D$1="LIFE+（キャンペーン）",VLOOKUP(C17,#REF!,2,FALSE),IF($D$1="LIFE（キャンペーン）",VLOOKUP(C17,#REF!,2,FALSE))))))) -> #REF! | F17: =IF($D$1="LACIE",VLOOKUP(C17,#REF!,3,FALSE),IF($D$1="LIFE+",VLOOKUP(C17,#REF!,3,FALSE),IF($D$1="LIFE",VLOOKUP(C17,#REF!,3,FALSE),IF($D$1="BASE",VLOOKUP(C17,#REF!,3,FALSE),IF($D$1="LIFE+（キャンペーン）",VLOOKUP(C17,#REF!,3,FALSE),IF($D$1="LIFE（キャンペーン）",VLOOKUP(C17,#REF!,3,FALSE))))))) -> #REF!
A18: □ | B18: 16 | C18: トラブル防止 | D18: =IF($D$1="LACIE",VLOOKUP(C18,#REF!,2,FALSE),IF($D$1="LIFE+",VLOOKUP(C18,#REF!,2,FALSE),IF($D$1="LIFE",VLOOKUP(C18,#REF!,2,FALSE),IF($D$1="BASE",VLOOKUP(C18,#REF!,2,FALSE),IF($D$1="LIFE+（キャンペーン）",VLOOKUP(C18,#REF!,2,FALSE),IF($D$1="LIFE（キャンペーン）",VLOOKUP(C18,#REF!,2,FALSE))))))) -> #REF! | F18: =IF($D$1="LACIE",VLOOKUP(C18,#REF!,3,FALSE),IF($D$1="LIFE+",VLOOKUP(C18,#REF!,3,FALSE),IF($D$1="LIFE",VLOOKUP(C18,#REF!,3,FALSE),IF($D$1="BASE",VLOOKUP(C18,#REF!,3,FALSE),IF($D$1="LIFE+（キャンペーン）",VLOOKUP(C18,#REF!,3,FALSE),IF($D$1="LIFE（キャンペーン）",VLOOKUP(C18,#REF!,3,FALSE))))))) -> #REF!
A19: □ | B19: 17 | C19: オプション | D19: =IF($D$1="LACIE",VLOOKUP(C19,#REF!,2,FALSE),IF($D$1="LIFE+",VLOOKUP(C19,#REF!,2,FALSE),IF($D$1="LIFE",VLOOKUP(C19,#REF!,2,FALSE),IF($D$1="BASE",VLOOKUP(C19,#REF!,2,FALSE),IF($D$1="LIFE+（キャンペーン）",VLOOKUP(C19,#REF!,2,FALSE),IF($D$1="LIFE（キャンペーン）",VLOOKUP(C19,#REF!,2,FALSE))))))) -> #REF! | F19: =IF($D$1="LACIE",VLOOKUP(C19,#REF!,3,FALSE),IF($D$1="LIFE+",VLOOKUP(C19,#REF!,3,FALSE),IF($D$1="LIFE",VLOOKUP(C19,#REF!,3,FALSE),IF($D$1="BASE",VLOOKUP(C19,#REF!,3,FALSE),IF($D$1="LIFE+（キャンペーン）",VLOOKUP(C19,#REF!,3,FALSE),IF($D$1="LIFE（キャンペーン）",VLOOKUP(C19,#REF!,3,FALSE))))))) -> #REF!
A20: □ | B20: 18 | C20: 式典 | D20: =IF($D$1="LACIE",VLOOKUP(C20,#REF!,2,FALSE),IF($D$1="LIFE+",VLOOKUP(C20,#REF!,2,FALSE),IF($D$1="LIFE",VLOOKUP(C20,#REF!,2,FALSE),IF($D$1="BASE",VLOOKUP(C20,#REF!,2,FALSE),IF($D$1="LIFE+（キャンペーン）",VLOOKUP(C20,#REF!,2,FALSE),IF($D$1="LIFE（キャンペーン）",VLOOKUP(C20,#REF!,2,FALSE))))))) -> #REF! | F20: =IF($D$1="LACIE",VLOOKUP(C20,#REF!,3,FALSE),IF($D$1="LIFE+",VLOOKUP(C20,#REF!,3,FALSE),IF($D$1="LIFE",VLOOKUP(C20,#REF!,3,FALSE),IF($D$1="BASE",VLOOKUP(C20,#REF!,3,FALSE),IF($D$1="LIFE+（キャンペーン）",VLOOKUP(C20,#REF!,3,FALSE),IF($D$1="LIFE（キャンペーン）",VLOOKUP(C20,#REF!,3,FALSE))))))) -> #REF!
A21: □ | B21: 19 | C21: 施工会社 | D21: =IF($D$1="LACIE",VLOOKUP(C21,#REF!,2,FALSE),IF($D$1="LIFE+",VLOOKUP(C21,#REF!,2,FALSE),IF($D$1="LIFE",VLOOKUP(C21,#REF!,2,FALSE),IF($D$1="BASE",VLOOKUP(C21,#REF!,2,FALSE),IF($D$1="LIFE+（キャンペーン）",VLOOKUP(C21,#REF!,2,FALSE),IF($D$1="LIFE（キャンペーン）",VLOOKUP(C21,#REF!,2,FALSE))))))) -> #REF! | F21: =IF($D$1="LACIE",VLOOKUP(C21,#REF!,3,FALSE),IF($D$1="LIFE+",VLOOKUP(C21,#REF!,3,FALSE),IF($D$1="LIFE",VLOOKUP(C21,#REF!,3,FALSE),IF($D$1="BASE",VLOOKUP(C21,#REF!,3,FALSE),IF($D$1="LIFE+（キャンペーン）",VLOOKUP(C21,#REF!,3,FALSE),IF($D$1="LIFE（キャンペーン）",VLOOKUP(C21,#REF!,3,FALSE))))))) -> #REF!
A22: □ | B22: 20 | C22: YouTube | D22: =IF($D$1="LACIE",VLOOKUP(C22,#REF!,2,FALSE),IF($D$1="LIFE+",VLOOKUP(C22,#REF!,2,FALSE),IF($D$1="LIFE",VLOOKUP(C22,#REF!,2,FALSE),IF($D$1="BASE",VLOOKUP(C22,#REF!,2,FALSE),IF($D$1="LIFE+（キャンペーン）",VLOOKUP(C22,#REF!,2,FALSE),IF($D$1="LIFE（キャンペーン）",VLOOKUP(C22,#REF!,2,FALSE))))))) -> #REF! | F22: =IF($D$1="LACIE",VLOOKUP(C22,#REF!,3,FALSE),IF($D$1="LIFE+",VLOOKUP(C22,#REF!,3,FALSE),IF($D$1="LIFE",VLOOKUP(C22,#REF!,3,FALSE),IF($D$1="BASE",VLOOKUP(C22,#REF!,3,FALSE),IF($D$1="LIFE+（キャンペーン）",VLOOKUP(C22,#REF!,3,FALSE),IF($D$1="LIFE（キャンペーン）",VLOOKUP(C22,#REF!,3,FALSE))))))) -> #REF!
A23: □ | B23: 21 | C23: お引渡し | D23: =IF($D$1="LACIE",VLOOKUP(C23,#REF!,2,FALSE),IF($D$1="LIFE+",VLOOKUP(C23,#REF!,2,FALSE),IF($D$1="LIFE",VLOOKUP(C23,#REF!,2,FALSE),IF($D$1="BASE",VLOOKUP(C23,#REF!,2,FALSE),IF($D$1="LIFE+（キャンペーン）",VLOOKUP(C23,#REF!,2,FALSE),IF($D$1="LIFE（キャンペーン）",VLOOKUP(C23,#REF!,2,FALSE))))))) -> #REF! | F23: =IF($D$1="LACIE",VLOOKUP(C23,#REF!,3,FALSE),IF($D$1="LIFE+",VLOOKUP(C23,#REF!,3,FALSE),IF($D$1="LIFE",VLOOKUP(C23,#REF!,3,FALSE),IF($D$1="BASE",VLOOKUP(C23,#REF!,3,FALSE),IF($D$1="LIFE+（キャンペーン）",VLOOKUP(C23,#REF!,3,FALSE),IF($D$1="LIFE（キャンペーン）",VLOOKUP(C23,#REF!,3,FALSE))))))) -> #REF!
A24: □ | B24: 22 | C24: お引越し | D24: =IF($D$1="LACIE",VLOOKUP(C24,#REF!,2,FALSE),IF($D$1="LIFE+",VLOOKUP(C24,#REF!,2,FALSE),IF($D$1="LIFE",VLOOKUP(C24,#REF!,2,FALSE),IF($D$1="BASE",VLOOKUP(C24,#REF!,2,FALSE),IF($D$1="LIFE+（キャンペーン）",VLOOKUP(C24,#REF!,2,FALSE),IF($D$1="LIFE（キャンペーン）",VLOOKUP(C24,#REF!,2,FALSE))))))) -> #REF! | F24: =IF($D$1="LACIE",VLOOKUP(C24,#REF!,3,FALSE),IF($D$1="LIFE+",VLOOKUP(C24,#REF!,3,FALSE),IF($D$1="LIFE",VLOOKUP(C24,#REF!,3,FALSE),IF($D$1="BASE",VLOOKUP(C24,#REF!,3,FALSE),IF($D$1="LIFE+（キャンペーン）",VLOOKUP(C24,#REF!,3,FALSE),IF($D$1="LIFE（キャンペーン）",VLOOKUP(C24,#REF!,3,FALSE))))))) -> #REF!
... A26: □ | B26: 24 | C26: LINE メール | D26: =IF($D$1="LACIE",VLOOKUP(C26,#REF!,2,FALSE),IF($D$1="LIFE+",VLOOKUP(C26,#REF!,2,FALSE),IF($D$1="LIFE",VLOOKUP(C26,#REF!,2,FALSE),IF($D$1="BASE",VLOOKUP(C26,#REF!,2,FALSE),IF($D$1="LIFE+（キャンペーン）",VLOOKUP(C26,#REF!,2,FALSE),IF($D$1="LIFE（キャンペーン）",VLOOKUP(C26,#REF!,2,FALSE))))))) -> #REF! | F26: =IF($D$1="LACIE",VLOOKUP(C26,#REF!,3,FALSE),IF($D$1="LIFE+",VLOOKUP(C26,#REF!,3,FALSE),IF($D$1="LIFE",VLOOKUP(C26,#REF!,3,FALSE),IF($D$1="BASE",VLOOKUP(C26,#REF!,3,FALSE),IF($D$1="LIFE+（キャンペーン）",VLOOKUP(C26,#REF!,3,FALSE),IF($D$1="LIFE（キャンペーン）",VLOOKUP(C26,#REF!,3,FALSE))))))) -> #REF!
E28: 住所 | F28: =初期入力!B5 -> 0
E30: 氏名 | F30: =初期入力!B4 -> 0 | G30: 印
E32: 住所 | F32: =IF(初期入力!B7="","",初期入力!B7)
E34: 氏名 | F34: =IF(初期入力!B6="","",初期入力!B6) | G34: 印

Sheet HOURS制約事項
D1: HOURS | E1: の仕様 制約事項一覧 | I1: ←商品名タブにて選択必要
C2: 項目 | D2: 標準内容 | F2: 備考
A3: □ | B3: 1 | C3: =IF($D$1="HOURS",作業用タブ2!D34,作業用タブ2!D3) -> 間取り | D3: =IF($D$1="LIFE LIMITED(キャンペーン)",VLOOKUP(C3,作業用タブ2!$D$2:$F$29,2,FALSE),IF($D$1="HOURS",VLOOKUP(C3,作業用タブ2!$D$33:$F$61,2,FALSE),IF($D$1="LIFE+ LIMITED(キャンペーン)",VLOOKUP(C3,作業用タブ2!$D$2:$F$29,2,FALSE)))) -> 完全自由設計 ※4マス×910mm間隔に柱または壁の設置が必要です。 | F3: =IF($D$1="LIFE LIMITED(キャンペーン)",VLOOKUP(C3,作業用タブ2!$D$2:$F$29,3,FALSE),IF($D$1="HOURS",VLOOKUP(C3,作業用タブ2!$D$33:$F$61,3,FALSE),IF($D$1="LIFE+ LIMITED(キャンペーン)",VLOOKUP(C3,作業用タブ2!$D$2:$F$29,3,FALSE)))) -> 申請業務に進んでいくため、基本設計確定後の変更は出来ません。
A4: □ | B4: 2 | C4: =IF($D$1="HOURS",作業用タブ2!D35,作業用タブ2!D4) -> 坪単価 | D4: =IF($D$1="LIFE LIMITED(キャンペーン)",VLOOKUP(C4,作業用タブ2!$D$2:$F$29,2,FALSE),IF($D$1="HOURS",VLOOKUP(C4,作業用タブ2!$D$33:$F$61,2,FALSE),IF($D$1="LIFE+ LIMITED(キャンペーン)",VLOOKUP(C4,作業用タブ2!$D$2:$F$29,2,FALSE)))) -> 本体工事価格は63万円(税別) 30坪未満の場合割増計算となり、1坪下がる度に15,000円×坪数＝追加費用が発生します。 3階建ての場合は坪単価＋40,000円UP 下屋の場合は下屋部分㎡×30,000円UP | F4: =IF($D$1="LIFE LIMITED(キャンペーン)",VLOOKUP(C4,作業用タブ2!$D$2:$F$29,3,FALSE),IF($D$1="HOURS",VLOOKUP(C4,作業用タブ2!$D$33:$F$61,3,FALSE),IF($D$1="LIFE+ LIMITED(キャンペーン)",VLOOKUP(C4,作業用タブ2!$D$2:$F$29,3,FALSE)))) -> 例)28坪の場合、30坪に対して2坪下がる 30,000円×28坪＝840,000円UP
A5: □ | B5: 3 | C5: 施工面積 | D5: =IF($D$1="LIFE LIMITED(キャンペーン)",VLOOKUP(C5,作業用タブ2!$D$2:$F$29,2,FALSE),IF($D$1="HOURS",VLOOKUP(C5,作業用タブ2!$D$33:$F$61,2,FALSE),IF($D$1="LIFE+ LIMITED(キャンペーン)",VLOOKUP(C5,作業用タブ2!$D$2:$F$29,2,FALSE)))) -> 建物価格は「施工面積 × 坪単価」にて算出します。 施工面積は、延床面積に加え、外壁に三方を囲まれたビルトインガレージ、半ビルトインガレージを含み、当社基準により算出します。 また、以下の工事は、施工面積に含まれていない場合でも、別途費用が加算されます。 ① 軒の出・オーバーハング工事 ：42,000円／㎡（税別） ② 下屋工事 ：30,000円／㎡（税別） ③ バルコニー工事・吹抜工事 ：60,000円／㎡（税別） ※対象となる面積は、設計図書に基づき当社が算出します。 | F5: =IF($D$1="LIFE LIMITED(キャンペーン)",VLOOKUP(C5,作業用タブ2!$D$2:$F$29,3,FALSE),IF($D$1="HOURS",VLOOKUP(C5,作業用タブ2!$D$33:$F$61,3,FALSE),IF($D$1="LIFE+ LIMITED(キャンペーン)",VLOOKUP(C5,作業用タブ2!$D$2:$F$29,3,FALSE)))) -> 左記内容の対象となる面積については別紙1の参考写真をご確認下さい。
A6: □ | B6: 4 | C6: =IF($D$1="HOURS",作業用タブ2!D37,作業用タブ2!D5) -> 住宅ローン | D6: =IF($D$1="LIFE LIMITED(キャンペーン)",VLOOKUP(C6,作業用タブ2!$D$2:$F$29,2,FALSE),IF($D$1="HOURS",VLOOKUP(C6,作業用タブ2!$D$33:$F$61,2,FALSE),IF($D$1="LIFE+ LIMITED(キャンペーン)",VLOOKUP(C6,作業用タブ2!$D$2:$F$29,2,FALSE)))) -> 住宅ローンの手続きはお施主様自身でお願いします。 当社でしかご用意ができない書類や図面等はお渡しします。 | F6: =IF($D$1="LIFE LIMITED(キャンペーン)",VLOOKUP(C6,作業用タブ2!$D$2:$F$29,3,FALSE),IF($D$1="HOURS",VLOOKUP(C6,作業用タブ2!$D$33:$F$61,3,FALSE),IF($D$1="LIFE+ LIMITED(キャンペーン)",VLOOKUP(C6,作業用タブ2!$D$2:$F$29,3,FALSE)))) -> ※事前審査も同様
A7: □ | B7: 5 | C7: =IF($D$1="HOURS",作業用タブ2!D38,作業用タブ2!D6) -> 打ち合わせ 期間 | D7: =IF($D$1="LIFE LIMITED(キャンペーン)",VLOOKUP(C7,作業用タブ2!$D$2:$F$29,2,FALSE),IF($D$1="HOURS",VLOOKUP(C7,作業用タブ2!$D$33:$F$61,2,FALSE),IF($D$1="LIFE+ LIMITED(キャンペーン)",VLOOKUP(C7,作業用タブ2!$D$2:$F$29,2,FALSE)))) -> 最大3ヵ月間 (回数：6回) | F7: =IF($D$1="LIFE LIMITED(キャンペーン)",VLOOKUP(C7,作業用タブ2!$D$2:$F$29,3,FALSE),IF($D$1="HOURS",VLOOKUP(C7,作業用タブ2!$D$33:$F$61,3,FALSE),IF($D$1="LIFE+ LIMITED(キャンペーン)",VLOOKUP(C7,作業用タブ2!$D$2:$F$29,3,FALSE)))) -> 打ち合わせ回数6回以下で下記の特典があります。 6回：★10万円相当 5回：★★20万円相当 ※初回ヒアリングは除く
A8: □ | B8: 6 | C8: =IF($D$1="HOURS",作業用タブ2!D39,作業用タブ2!D7) -> 仕様 | D8: =IF($D$1="LIFE LIMITED(キャンペーン)",VLOOKUP(C8,作業用タブ2!$D$2:$F$29,2,FALSE),IF($D$1="HOURS",VLOOKUP(C8,作業用タブ2!$D$33:$F$61,2,FALSE),IF($D$1="LIFE+ LIMITED(キャンペーン)",VLOOKUP(C8,作業用タブ2!$D$2:$F$29,2,FALSE)))) -> セミオーダー制 当社の設計士がこだわり抜いた【 STYLE BOOK 】からのみ選択できます。 | F8: =IF($D$1="LIFE LIMITED(キャンペーン)",VLOOKUP(C8,作業用タブ2!$D$2:$F$29,3,FALSE),IF($D$1="HOURS",VLOOKUP(C8,作業用タブ2!$D$33:$F$61,3,FALSE),IF($D$1="LIFE+ LIMITED(キャンペーン)",VLOOKUP(C8,作業用タブ2!$D$2:$F$29,3,FALSE))))
A9: □ | B9: 7 | C9: =IF($D$1="HOURS",作業用タブ2!D40,作業用タブ2!D8) -> 長期優良住宅 | D9: =IF($D$1="LIFE LIMITED(キャンペーン)",VLOOKUP(C9,作業用タブ2!$D$2:$F$29,2,FALSE),IF($D$1="HOURS",VLOOKUP(C9,作業用タブ2!$D$33:$F$61,2,FALSE),IF($D$1="LIFE+ LIMITED(キャンペーン)",VLOOKUP(C9,作業用タブ2!$D$2:$F$29,2,FALSE)))) -> 認定基準として、少なくとも1の階の床面積(階段部分を除く)が40㎡以上かつ床面積の合計75㎡必要です。 また、都市計画法第53条許可の対象となる地域では認定対象外です。 | F9: =IF($D$1="LIFE LIMITED(キャンペーン)",VLOOKUP(C9,作業用タブ2!$D$2:$F$29,3,FALSE),IF($D$1="HOURS",VLOOKUP(C9,作業用タブ2!$D$33:$F$61,3,FALSE),IF($D$1="LIFE+ LIMITED(キャンペーン)",VLOOKUP(C9,作業用タブ2!$D$2:$F$29,3,FALSE)))) -> 詳細は設計打ち合わせにてご確認ください。
A10: □ | B10: 8 | C10: =IF($D$1="HOURS",作業用タブ2!D41,作業用タブ2!D9) -> Ua値 | D10: =IF($D$1="LIFE LIMITED(キャンペーン)",VLOOKUP(C10,作業用タブ2!$D$2:$F$29,2,FALSE),IF($D$1="HOURS",VLOOKUP(C10,作業用タブ2!$D$33:$F$61,2,FALSE),IF($D$1="LIFE+ LIMITED(キャンペーン)",VLOOKUP(C10,作業用タブ2!$D$2:$F$29,2,FALSE)))) -> 0.46W/㎡･Kを目安としております。但し、間取りや窓の個数･種類によって数値が変わり、0.46W/㎡･Kを確保できない場合があります。 | F10: =IF($D$1="LIFE LIMITED(キャンペーン)",VLOOKUP(C10,作業用タブ2!$D$2:$F$29,3,FALSE),IF($D$1="HOURS",VLOOKUP(C10,作業用タブ2!$D$33:$F$61,3,FALSE),IF($D$1="LIFE+ LIMITED(キャンペーン)",VLOOKUP(C10,作業用タブ2!$D$2:$F$29,3,FALSE))))
A11: □ | B11: 9 | C11: =IF($D$1="HOURS",作業用タブ2!D42,作業用タブ2!D10) -> 窓 | D11: =IF($D$1="LIFE LIMITED(キャンペーン)",VLOOKUP(C11,作業用タブ2!$D$2:$F$29,2,FALSE),IF($D$1="HOURS",VLOOKUP(C11,作業用タブ2!$D$33:$F$61,2,FALSE),IF($D$1="LIFE+ LIMITED(キャンペーン)",VLOOKUP(C11,作業用タブ2!$D$2:$F$29,2,FALSE)))) -> 施工面積が35坪未満12ヵ所、35～40坪13ヵ所、40～45坪14ヵ所、45～50坪15ヵ所、50坪以上16ヵ所までが標準個数です。 ※既製品のみ選定可能とし特注品の選択不可。 | F11: =IF($D$1="LIFE LIMITED(キャンペーン)",VLOOKUP(C11,作業用タブ2!$D$2:$F$29,3,FALSE),IF($D$1="HOURS",VLOOKUP(C11,作業用タブ2!$D$33:$F$61,3,FALSE),IF($D$1="LIFE+ LIMITED(キャンペーン)",VLOOKUP(C11,作業用タブ2!$D$2:$F$29,3,FALSE)))) -> 掃き出し窓(手動シャッター付)H2200は2ヵ所まで
A12: □ | B12: 10 | C12: =IF($D$1="HOURS",作業用タブ2!D43,作業用タブ2!D11) -> 建具 | D12: =IF($D$1="LIFE LIMITED(キャンペーン)",VLOOKUP(C12,作業用タブ2!$D$2:$F$29,2,FALSE),IF($D$1="HOURS",VLOOKUP(C12,作業用タブ2!$D$33:$F$61,2,FALSE),IF($D$1="LIFE+ LIMITED(キャンペーン)",VLOOKUP(C12,作業用タブ2!$D$2:$F$29,2,FALSE)))) -> 開き扉H2400㎜標準(各居室・トイレ・脱衣室・ランドリーそれぞれ1ヵ所ずつ) ※片引き戸2ヵ所まで標準 | F12: =IF($D$1="LIFE LIMITED(キャンペーン)",VLOOKUP(C12,作業用タブ2!$D$2:$F$29,3,FALSE),IF($D$1="HOURS",VLOOKUP(C12,作業用タブ2!$D$33:$F$61,3,FALSE),IF($D$1="LIFE+ LIMITED(キャンペーン)",VLOOKUP(C12,作業用タブ2!$D$2:$F$29,3,FALSE)))) -> 引き戸3枚目以上及び収納扉等、リビング・書斎・洗面室・ファミリーCL・その他の部屋はオプションです。
A13: □ | B13: 11 | C13: 床材 | D13: =IF($D$1="LIFE LIMITED(キャンペーン)",VLOOKUP(C13,作業用タブ2!$D$2:$F$29,2,FALSE),IF($D$1="HOURS",VLOOKUP(C13,作業用タブ2!$D$33:$F$61,2,FALSE),IF($D$1="LIFE+ LIMITED(キャンペーン)",VLOOKUP(C13,作業用タブ2!$D$2:$F$29,2,FALSE)))) -> 無垢床材を使用した場合、伸縮、床鳴り、及び経年劣化による変色が発生 する場合があります。 | F13: =IF($D$1="LIFE LIMITED(キャンペーン)",VLOOKUP(C13,作業用タブ2!$D$2:$F$29,3,FALSE),IF($D$1="HOURS",VLOOKUP(C13,作業用タブ2!$D$33:$F$61,3,FALSE),IF($D$1="LIFE+ LIMITED(キャンペーン)",VLOOKUP(C13,作業用タブ2!$D$2:$F$29,3,FALSE)))) -> 0
A14: □ | B14: 12 | C14: 換気システム | D14: =IF($D$1="LIFE LIMITED(キャンペーン)",VLOOKUP(C14,作業用タブ2!$D$2:$F$29,2,FALSE),IF($D$1="HOURS",VLOOKUP(C14,作業用タブ2!$D$33:$F$61,2,FALSE),IF($D$1="LIFE+ LIMITED(キャンペーン)",VLOOKUP(C14,作業用タブ2!$D$2:$F$29,2,FALSE)))) -> 換気システムは全熱交換型第一種換気システム(Panasonic)が標準です。 | F14: =IF($D$1="LIFE LIMITED(キャンペーン)",VLOOKUP(C14,作業用タブ2!$D$2:$F$29,3,FALSE),IF($D$1="HOURS",VLOOKUP(C14,作業用タブ2!$D$33:$F$61,3,FALSE),IF($D$1="LIFE+ LIMITED(キャンペーン)",VLOOKUP(C14,作業用タブ2!$D$2:$F$29,3,FALSE)))) -> DSDD換気システム(okatomi)はオプションとなり、請負契約までに確定が必要です。請負契約後は変更できません。
A15: □ | B15: 13 | C15: =IF($D$1="HOURS",作業用タブ2!D46,作業用タブ2!D17) -> ユニットバス | D15: =IF($D$1="LIFE LIMITED(キャンペーン)",VLOOKUP(C15,作業用タブ2!$D$2:$F$29,2,FALSE),IF($D$1="HOURS",VLOOKUP(C15,作業用タブ2!$D$33:$F$61,2,FALSE),IF($D$1="LIFE+ LIMITED(キャンペーン)",VLOOKUP(C15,作業用タブ2!$D$2:$F$29,2,FALSE)))) -> 天井有り | F15: =IF($D$1="LIFE LIMITED(キャンペーン)",VLOOKUP(C15,作業用タブ2!$D$2:$F$29,3,FALSE),IF($D$1="HOURS",VLOOKUP(C15,作業用タブ2!$D$33:$F$61,3,FALSE),IF($D$1="LIFE+ LIMITED(キャンペーン)",VLOOKUP(C15,作業用タブ2!$D$2:$F$29,3,FALSE)))) -> 天井無しの施工はDSDD換気システムをオプションで採用される場合のみ対応可能です。ご選択いただけるメーカーが限られますのでご注意ください。
A16: □ | B16: 14 | C16: =IF($D$1="HOURS",作業用タブ2!D47,作業用タブ2!D13) -> エコキュート タンク | D16: =IF($D$1="LIFE LIMITED(キャンペーン)",VLOOKUP(C16,作業用タブ2!$D$2:$F$29,2,FALSE),IF($D$1="HOURS",VLOOKUP(C16,作業用タブ2!$D$33:$F$61,2,FALSE),IF($D$1="LIFE+ LIMITED(キャンペーン)",VLOOKUP(C16,作業用タブ2!$D$2:$F$29,2,FALSE)))) -> 室外置き | F16: =IF($D$1="LIFE LIMITED(キャンペーン)",VLOOKUP(C16,作業用タブ2!$D$2:$F$29,3,FALSE),IF($D$1="HOURS",VLOOKUP(C16,作業用タブ2!$D$33:$F$61,3,FALSE),IF($D$1="LIFE+ LIMITED(キャンペーン)",VLOOKUP(C16,作業用タブ2!$D$2:$F$29,3,FALSE)))) -> 室内置きはオプションです。
A17: □ | B17: 15 | C17: =IF($D$1="HOURS",作業用タブ2!D48,作業用タブ2!D14) -> 点検口 | D17: =IF($D$1="LIFE LIMITED(キャンペーン)",VLOOKUP(C17,作業用タブ2!$D$2:$F$29,2,FALSE),IF($D$1="HOURS",VLOOKUP(C17,作業用タブ2!$D$33:$F$61,2,FALSE),IF($D$1="LIFE+ LIMITED(キャンペーン)",VLOOKUP(C17,作業用タブ2!$D$2:$F$29,2,FALSE)))) -> 換気システムや配管の定期点検および不具合が起きた場合に備えて1,2Fに必要な箇所に天井･床下点検口を3～4つ以上設置しています。 | F17: =IF($D$1="LIFE LIMITED(キャンペーン)",VLOOKUP(C17,作業用タブ2!$D$2:$F$29,3,FALSE),IF($D$1="HOURS",VLOOKUP(C17,作業用タブ2!$D$33:$F$61,3,FALSE),IF($D$1="LIFE+ LIMITED(キャンペーン)",VLOOKUP(C17,作業用タブ2!$D$2:$F$29,3,FALSE)))) -> 点検口の個数および位置については間取りプランにより変動します。
